Workbook

Sheet INF
A23: NOMBRE | B23: RFC | C23: N. COMERCIAL | D23: CLAVE | E23: F. DE PAGO | F23: CLAVE | G23: USO DE LA FACTURA | H23: CORREO | I23: DIRECCION
A24: EFREN ABUNDEZ REYNA | B24: AURE7306187IA | D24: 01 | E24: EFECTIVO | F24: G01 | G24: ADQUISICION DE MERCANCIA | H24: EFRENABUNDEZREINA@GMAIL.COM | I24: FACTURAS DE MENOS DE $4,000
A25: LUIS ALEJANDRO HERNANDEZ REYNA | B25: HERL850705AL2 | C25: LOS CARACOLES | D25: 03 | E25: PAGO TRANSFERENCIA | F25: G01 | G25: ADQUISICION DE MERCANCIA | H25: alexhdzre@gmail.com
A26: ANA BEATRIZ ESTRADA ARGOTE | B26: EAAA860701UP2 | C26: MARISCOS MARLEY | D26: 03 | E26: PAGO TRANSFERENCIA | F26: G03 | G26: GASTO EN GENERAL
A27: SERGIO ROMERO DURAN | B27: RODS620908QAA | C27: YEYOS | D27: 01 | E27: EFECTIVO | F27: G01 | G27: ADQUISICION DE MERCANCIA | I27: FACTURAS DE MENOS DE $2,000
A28: MARIELA OLMOS GAONA | B28: OOGM010703NX1 | C28: MARISCOS MAR VELERO | D28: 01 | E28: PAGO TRANSFERENCIA | F28: G01 | G28: ADQUISICION DE MERCANCIA | H28: marveleroseafood@outlook.com | I28: David Galván Bermúdez 101 Col. Cristo Rey
A29: LUCIANO MIJAIL ORTEGA MUÑOZ | B29: OEML881105IK2 | D29: 01 | E29: PAGO TRANSFERENCIA | F29: G01 | G29: ADQUISICION DE MERCANCIA | H29: villaluna3107@gmail.com | I29: Brisas de San Simón 223 | J29: Colonia Brisas de San Nicolas | K29: Código Postal 37297
A30: GUSTAVO HUMBERTO VELASCO GALVEZ | B30: VEGG9211019T1 | C30: DELIMAR | E30: PAGO TRANSFERENCIA | F30: G01 | G30: ADQUISICION DE MERCANCIA
A31: JESUS AGUSTIN VELAZQUEZ FLORES | B31: VEFJ900303M65 | D31: 03 | E31: PAGO TRANSFERENCIA | F31: G01 | G31: ADQUISICION DE MERCANCIA
A32: KARLA ESTEFANIA SALAZAR FLORES | B32: SAFK9807277N1 | E32: EFECTIVO | G32: ADQUISICION DE MERCANCIA | J32: crisma-flores@hotmail.con
A33: ANGEL TERRAZAS MONROY | B33: TEMA7105035N4

Sheet P.F.A.E.
C4: PAGOS PROVISIONLAES REGIMEN DE PERSONAS FISICAS CON ACTIVIDADES EMPRESARIALES Y PROFESIONALES
C5: 1 | D5: 2 | E5: 3 | F5: 4 | G5: 5 | H5: 6 | I5: 7 | J5: 8 | K5: 9 | L5: 10 | M5: 11 | N5: 12
C6: ENERO | D6: FEBRERO | E6: MARZO | F6: ABRIL | G6: MAYO | H6: JUNIO | I6: JULIO | J6: AGOSTO | K6: SEPTIEMBRE | L6: OCTUBRE | M6: NOVIEMBRE | N6: DICIEMBRE | P6: DEL EJERCICIO | Q6: SALDO ANUAL
A7: INGRESOS DEL PERIODO | C7: =+'control p.y g.'!D3 -> 310579 | D7: =+'control p.y g.'!D4 -> 230572.03 | E7: =+'control p.y g.'!D5 -> 240808.89 | F7: =+'control p.y g.'!D6 -> 357091.76 | G7: =+'control p.y g.'!D7 -> 362431.69 | H7: =+'control p.y g.'!D8 -> 424706 | I7: =+'control p.y g.'!D9 -> 272396.1 | J7: =+'control p.y g.'!D10 -> 247594.93 | K7: =+'control p.y g.'!D11 -> 336307.21 | L7: =+'control p.y g.'!D12 -> 359882.55 | M7: =+'control p.y g.'!D13 -> 279550.69 | N7: =+'control p.y g.'!D14 -> 524795.93 | P7: =SUM(C7:O7) -> 3946716.8
A8: INGRESOS ACUMULABLES | C8: =C7+B8 -> 310579 | D8: =D7+C8 -> 541151.03 | E8: =E7+D8 -> 781959.92 | F8: =F7+E8 -> 1139051.7 | G8: =G7+F8 -> 1501483.4 | H8: =H7+G8 -> 1926189.4 | I8: =I7+H8 -> 2198585.5 | J8: =J7+I8 -> 2446180.4 | ... N8: =N7+M8 -> 3946716.8 | P8: =P7 -> 3946716.8 | Q8: =SUM(C7:N7) -> 3946716.8
A10: DEDUCCIONES PERSONALES | C10: 0 | D10: 0 | E10: 0 | F10: 0 | G10: 0 | H10: 0 | I10: 0 | J10: 0 | K10: 0 | L10: 0 | M10: 0 | N10: 0 | O10: 0 | P10: =SUM(C10:O10) -> 0
A11: SUELDOS Y SALARIOS | B11: 502 | C11: 0 | P11: =SUM(C11:N11) -> 0
A12: DEPRECIACIONES | B12: 560 | P12: =SUM(C12:N12) -> 0
A13: DEDUCCIONES DEL PERIODO | C13: =+'control p.y g.'!C3 -> 303686.29 | D13: =+'control p.y g.'!C4 -> 224265.94 | E13: =+'control p.y g.'!C5 -> 236808.89 | F13: =+'control p.y g.'!C6 -> 354090.89 | G13: =+'control p.y g.'!C7 -> 359428.77 | H13: =+'control p.y g.'!C8 -> 426702.99 | I13: =+'control p.y g.'!C9 -> 260003.44 | J13: =+'control p.y g.'!C10 -> 240167.35 | K13: =+'control p.y g.'!C11 -> 329447.37 | L13: =+'control p.y g.'!C12 -> 355882.93 | M13: =+'control p.y g.'!C13 -> 275458.4 | N13: =+'control p.y g.'!C14 -> 520718.05 | P13: =SUM(C13:O13) -> 3886661.3
A14: TOTAL DE DEDUCCIONES | C14: =C13+C11+C12 -> 303686.29 | D14: =D13+D12+C14+D11 -> 527952.23 | E14: =E13+E12+D14+E11 -> 764761.12 | F14: =F13+F12+E14+F11 -> 1118852 | G14: =G13+G12+F14+G11 -> 1478280.8 | H14: =H13+H12+G14+H11 -> 1904983.8 | I14: =I13+I12+H14+I11 -> 2164987.2 | J14: =J13+J12+I14+J11 -> 2405154.6 | K14: =K13+K12+J14+K11 -> 2734601.9 | ... N14: =N13+N12+M14+N11 -> 3886661.3 | P14: =SUM(P10:P13) -> 3886661.3 | Q14: =SUM(C13:N13) -> 3886661.3
A16: PERIDA FISCAL EJ. ANTES. | P16: =IF(P8-P14>0,N16,0) -> 0
A18: BASE GRAVABLE | C18: =IF((C8-C14-C16)>0,(C8-C14-C16),0) -> 6892.71 | D18: =IF((D8-D14-D16)>0,(D8-D14-D16),0) -> 13198.804 | E18: =IF((E8-E14-E16)>0,(E8-E14-E16),0) -> 17198.798 | F18: =IF((F8-F14-F16)>0,(F8-F14-F16),0) -> 20199.664 | G18: =IF((G8-G14-G16)>0,(G8-G14-G16),0) -> 23202.583 | H18: =IF((H8-H14-H16)>0,(H8-H14-H16),0) -> 21205.593 | I18: =IF((I8-I14-I16)>0,(I8-I14-I16),0) -> 33598.256 | J18: =IF((J8-J14-J16)>0,(J8-J14-J16),0) -> 41025.842 | ... N18: =IF((N8-N14-N16)>0,(N8-N14-N16),0) -> 60055.477 | P18: =IF((P8-P14-P16)>0,P8-P14-P16,0) -> 60055.477 | Q18: =Q8-Q14 -> 60055.477
A20: - LIMITE INFERIOR | C20: =IF(C18>0,VLOOKUP(C18,'T ISR'!A5:B15,1,1),0) -> 6332.06 | D20: =IF(D18>0,VLOOKUP(D18,'T ISR'!F5:G15,1,1),0) -> 12664.11 | E20: =IF(E18>0,VLOOKUP(E18,'T ISR'!A21:B30,1,1),0) -> 2238.13 | F20: =IF(F18>0,VLOOKUP(F18,'T ISR'!F21:G31,1,1),0) -> 2984.17 | G20: =IF(G18>0,VLOOKUP(G18,'T ISR'!A37:B47,1,1),0) -> 3730.21 | H20: =IF(H18>0,VLOOKUP(H18,'T ISR'!F37:G47,1,1),0) -> 4476.25 | I20: =IF(I18>0,VLOOKUP(I18,'T ISR'!A53:B63,1,1),0) -> 5222.29 | J20: =IF(J18>0,VLOOKUP(J18,'T ISR'!F53:G63,1,1),0) -> 5968.33 | K20: =IF(K18>0,VLOOKUP(K18,'T ISR'!A69:B79,1,1),0) -> 6714.37 | L20: =IF(L18>0,VLOOKUP(L18,'T ISR'!F69:G79,1,1),0) -> 7460.41 | M20: =IF(M18>0,VLOOKUP(M18,'T ISR'!A85:B95,1,1),0) -> 8206.45 | N20: =IF(N18>0,VLOOKUP(N18,'T ISR'!F85:G95,1,1),0) -> 8952.5
A22: = EXCEDENTE S/LIM INF. | C22: =C18-C20 -> 560.65 | D22: =D18-D20 -> 534.69448 | E22: =E18-E20 -> 14960.668 | F22: =F18-F20 -> 17215.494 | G22: =G18-G20 -> 19472.373 | H22: =H18-H20 -> 16729.343 | I22: =I18-I20 -> 28375.966 | J22: =J18-J20 -> 35057.512 | ... N22: =N18-N20 -> 51102.977
A24: x % DE TASA | C24: =IF(C18>0,VLOOKUP(C28,'T ISR'!C5:D15,2,0),0) -> 0.1088 | D24: =VLOOKUP(D18,'T ISR'!F5:I15,4,1) -> 0.1088 | E24: =VLOOKUP(E18,'T ISR'!A21:D31,4,1) -> 0.064 | F24: =VLOOKUP(F18,'T ISR'!F21:I31,4,1) -> 0.064 | G24: =VLOOKUP(G18,'T ISR'!A37:D47,4,1) -> 0.064 | H24: =VLOOKUP(H18,'T ISR'!F37:I47,4,1) -> 0.064 | I24: =VLOOKUP(I18,'T ISR'!A53:D63,4,1) -> 0.064 | J24: =VLOOKUP(J18,'T ISR'!F53:I63,4,1) -> 0.064 | K24: =VLOOKUP(K18,'T ISR'!A69:D79,4,1) -> 0.064 | L24: =VLOOKUP(L18,'T ISR'!F69:I79,4,1) -> 0.064 | M24: =VLOOKUP(M18,'T ISR'!A85:D95,4,1) -> 0.064 | N24: =VLOOKUP(N18,'T ISR'!F85:I95,4,1) -> 0.064
A26: = IMPUESTO MARGINAL | C26: =C22*C24 -> 60.99872 | D26: =D22*D24 -> 58.17476 | E26: =E22*E24 -> 957.48274 | F26: =F22*F24 -> 1101.7916 | G26: =G22*G24 -> 1246.2319 | H26: =H22*H24 -> 1070.6779 | I26: =I22*I24 -> 1816.0619 | J26: =J22*J24 -> 2243.6807 | ... N26: =N22*N24 -> 3270.5905
A28: + CUOTA FIJA | C28: =IF(C18>0,VLOOKUP(C18,'T ISR'!A5:C15,3,1),0) -> 371.83 | D28: =IF(D18>0,VLOOKUP(D18,'T ISR'!F5:H15,3,1),0) -> 743.66 | E28: =IF(E18>0,VLOOKUP(E18,'T ISR'!A21:C31,3,1),0) -> 42.96 | F28: =IF(F18>0,VLOOKUP(F18,'T ISR'!F21:H31,3,1),0) -> 57.28 | G28: =IF(G18>0,VLOOKUP(G18,'T ISR'!A37:C47,3,1),0) -> 71.6 | H28: =IF(H18>0,VLOOKUP(H18,'T ISR'!F37:H47,3,1),0) -> 85.92 | I28: =IF(I18>0,VLOOKUP(I18,'T ISR'!A53:C63,3,1),0) -> 100.24 | J28: =IF(J18>0,VLOOKUP(J18,'T ISR'!F53:H63,3,1),0) -> 114.56 | K28: =IF(K18>0,VLOOKUP(K18,'T ISR'!A69:C79,3,1),0) -> 128.88 | L28: =IF(L18>0,VLOOKUP(L18,'T ISR'!F69:H79,3,1),0) -> 143.2 | M28: =IF(M18>0,VLOOKUP(M18,'T ISR'!A85:C95,3,1),0) -> 157.52 | N28: =IF(N18>0,VLOOKUP(N18,'T ISR'!F85:H95,3,1),0) -> 171.88
A30: = IMPUESTO DETERMINADO | C30: =C26+C28 -> 432.82872 | D30: =D26+D28 -> 801.83476 | E30: =E26+E28 -> 1000.4427 | F30: =F26+F28 -> 1159.0716 | G30: =G26+G28 -> 1317.8319 | H30: =H26+H28 -> 1156.5979 | I30: =I26+I28 -> 1916.3019 | J30: =J26+J28 -> 2358.2407 | ... O30: =O26+O28 -> 0
A32: - PAGO PROVISIONAL | C32: 0 | D32: =IF(C36>0,C32+C33+C35+C36,C32+C33+C35) -> 432.82872 | E32: =IF(D36>0,D32+D33+D35+D36,D32+D33+D35) -> 801.83476 | F32: =IF(E36>0,E32+E33+E35+E36,E32+E33+E35) -> 1000.4427 | G32: =IF(F36>0,F32+F33+F35+F36,F32+F33+F35) -> 1159.0716 | H32: =IF(G36>0,G32+G33+G35+G36,G32+G33+G35) -> 1317.8319 | I32: =IF(H36>0,H32+H33+H35+H36,H32+H33+H35) -> 1317.8319 | J32: =IF(I36>0,I32+I33+I35+I36,I32+I33+I35) -> 1916.3019 | K32: =IF(J36>0,J32+J33+J35+J36,J32+J33+J35) -> 2358.2407 | ... N32: =IF(M36>0,M32+M33+M35+M36,M32+M33+M35) -> 3214.8732
A33: - SUBSIDIO PARA EL EMPLEO | C33: 0 | D33: 0 | E33: 0 | F33: 0 | G33: 0 | H33: 0 | I33: 0 | J33: 0 | K33: 0 | L33: 0 | M33: 0 | N33: 0
A34: - I.S.R. RETENIDO | C34: 0 | D34: 0 | E34: 0 | F34: 0 | G34: 0 | H34: 0 | I34: 0 | J34: 0 | K34: 0 | L34: 0 | M34: 0 | N34: 0 | Q34: =SUM(C34:N34) -> 0
A36: = ISR POR PAGAR | B36: 1 | C36: =IF((C30-C32-C33-C34)>0,C30-C32-C33-C34,0) -> 432.82872 | D36: =IF((D30-D32-D33-D34)>0,D30-D32-D33-D34,0) -> 369.00604 | E36: =IF((E30-E32-E33-E34)>0,E30-E32-E33-E34,0) -> 198.60798 | F36: =IF((F30-F32-F33-F34)>0,F30-F32-F33-F34,0) -> 158.62891 | G36: =IF((G30-G32-G33-G34)>0,G30-G32-G33-G34,0) -> 158.76022 | H36: =IF((H30-H32-H33-H34)>0,H30-H32-H33-H34,0) -> 0 | I36: =IF((I30-I32-I33-I34)>0,I30-I32-I33-I34,0) -> 598.46999 | J36: =IF((J30-J32-J33-J34)>0,J30-J32-J33-J34,0) -> 441.93888 | ... N36: =IF((N30-N32-N33-N34)>0,N30-N32-N33-N34,0) -> 227.59731 | Q36: =SUM(B36:P36) -> 3443.4705

Sheet IVA
A2: DETERMINACION DE IVA
A3: PERSONAS FISICAS CON ACTIVIDADES EMPRESARIALES
A5: Cta. Ing. X Vta | B5: Concepto | C5: Ene | D5: Feb | E5: Mar | F5: Abr | G5: May | H5: Jun | I5: Jul | J5: Ago | K5: Sep | L5: Oct | M5: Nov | N5: Dic | O5: TOTAL
C6: 1 | D6: 2 | E6: 3 | F6: 4 | G6: 5 | H6: 6 | I6: 7 | J6: 8 | K6: 9 | L6: 10 | M6: 11 | N6: 12
B8: IVA CAUSADO
A9: 12 | B9: Ingresos Gravados al 16% | C9: 0 | D9: =+ING!K17+ING!K23 -> 304.16552 | E9: 0 | F9: 137.24 | G9: 207.31 | H9: 0 | I9: 418.1 | J9: 0 | K9: 0 | L9: 0 | M9: 0 | N9: 0 | O9: =SUM(C9:N9) -> 1066.8155
A10: 13 | B10: Ingresos Gravados al 8% | C10: 0 | D10: 0 | E10: 0 | F10: 0 | G10: 0 | H10: 0 | I10: 0 | J10: 0 | K10: 0 | L10: 0 | M10: 0 | N10: 0 | O10: =SUM(C10:N10) -> 0
A11: 3 | B11: Ingresos Gravados al 0% | C11: =+'P.F.A.E.'!C9 -> 0 | D11: =+ING!J15+ING!J16+ING!J18+ING!J19+ING!J20+ING!J21+ING!J22+ING!J24+ING!J30 -> 228671 | E11: =+'P.F.A.E.'!E7 -> 240808.89 | F11: =+'P.F.A.E.'!F7 -> 357091.76 | G11: =+'P.F.A.E.'!G7 -> 362431.69 | H11: =+'P.F.A.E.'!H7 -> 424706 | I11: =+'P.F.A.E.'!I7 -> 272396.1 | J11: =+'P.F.A.E.'!J7 -> 247594.93 | K11: =+'P.F.A.E.'!K7 -> 336307.21 | L11: =+'P.F.A.E.'!L7 -> 359882.55 | ... N11: =+'P.F.A.E.'!N7 -> 524795.93 | O11: =SUM(C11:N11) -> 3634236.7
A12: 4 | B12: Ingresos Exentos | C12: 0 | D12: 0 | E12: 0 | F12: 0 | G12: 0 | H12: 0 | I12: 0 | J12: 0 | K12: 0 | L12: 0 | M12: 0 | N12: 0 | O12: =SUM(C12:N12) -> 0
A13: 1 | B13: Ingresos Gravados al 15% | C13: 0 | D13: 0 | E13: 0 | F13: 0 | G13: 0 | H13: 0 | I13: 0 | J13: 0 | K13: 0 | L13: 0 | M13: 0 | N13: 0 | O13: =SUM(C13:N13) -> 0
A14: 2 | B14: Ingresos Gravados al 10% | C14: 0 | D14: 0 | E14: 0 | F14: 0 | G14: 0 | H14: 0 | I14: 0 | J14: 0 | K14: 0 | L14: 0 | M14: 0 | N14: 0 | O14: =SUM(C14:N14) -> 0
A15: 5 | B15: Otras Bases | C15: 0 | D15: 0 | E15: 0 | F15: 0 | G15: 0 | H15: 0 | I15: 0 | J15: 0 | K15: 0 | L15: 0 | M15: 0 | N15: 0 | O15: =SUM(C15:N15) -> 0
B16: Total Ingresos | C16: =SUM(C9:C15) -> 0 | D16: =SUM(D9:D15) -> 228975.17 | E16: =SUM(E9:E15) -> 240808.89 | F16: =SUM(F9:F15) -> 357229 | G16: =SUM(G9:G15) -> 362639 | H16: =SUM(H9:H15) -> 424706 | I16: =SUM(I9:I15) -> 272814.2 | J16: =SUM(J9:J15) -> 247594.93 | ... N16: =SUM(N9:N15) -> 524795.93 | O16: =SUM(C16:N16) -> 3635303.6
A18: 12 | B18: IVA trasladado al 16% | C18: =C9*0.16 -> 0 | D18: =D9*0.16 -> 48.666483 | E18: =E9*0.16 -> 0 | F18: =F9*0.16 -> 21.9584 | G18: =G9*0.16 -> 33.1696 | H18: =H9*0.16 -> 0 | I18: =I9*0.16 -> 66.896 | J18: =J9*0.16 -> 0 | ... N18: =N9*0.16 -> 0 | O18: =SUM(C18:N18) -> 170.69048
A19: 13 | B19: IVA trasladado al 8% | C19: =C10*0.8% -> 0 | D19: =D10*0.8% -> 0 | E19: =E10*0.8% -> 0 | F19: =F10*0.8% -> 0 | G19: =G10*0.8% -> 0 | H19: =H10*0.8% -> 0 | I19: =I10*0.8% -> 0 | J19: =J10*0.8% -> 0 | ... N19: =N10*0.8% -> 0 | O19: =SUM(C19:N19) -> 0
A20: 8 | B20: IVA Retenido | C20: 0 | D20: 0 | E20: 0 | F20: 0 | G20: 0 | H20: 0 | I20: 0 | J20: 0 | K20: 0 | L20: 0 | M20: 0 | N20: 0 | O20: =SUM(C20:N20) -> 0
B21: Total IVA Trasladado | C21: =C18+C19-C20 -> 0 | D21: =D18+D19-D20 -> 48.666483 | E21: =E18+E19-E20 -> 0 | F21: =F18+F19-F20 -> 21.9584 | G21: =G18+G19-G20 -> 33.1696 | H21: =H18+H19-H20 -> 0 | I21: =I18+I19-I20 -> 66.896 | J21: =J18+J19-J20 -> 0 | ... O21: =O18+O19-O20 -> 170.69048
B23: IVA ACREDITABLE
A24: 12 | B24: Base gravable al 16% | C24: =+'control p.y g.'!I3 -> 303686.29 | D24: 36577 | E24: =+'control p.y g.'!I5 -> 12764.778 | F24: =+'control p.y g.'!I6 -> 7445.7775 | G24: =+'control p.y g.'!I7 -> 10422.32 | H24: =+'control p.y g.'!I8 -> 159173 | I24: =+'control p.y g.'!I9 -> 15790.578 | J24: =+'control p.y g.'!I10 -> 20983.1 | K24: =+'control p.y g.'!I11 -> 19558.553 | L24: =+'control p.y g.'!I12 -> 25572.574 | M24: =+'control p.y g.'!I13 -> 18207.446 | N24: =+'control p.y g.'!I14 -> 19375.174 | O24: =SUM(C24:N24) -> 649556.59
A25: 13 | B25: Base gravable al 8% | C25: 0 | D25: 0 | E25: 0 | F25: 0 | G25: 0 | H25: 0 | I25: 0 | J25: 0 | K25: 0 | L25: 0 | M25: 0 | N25: 0 | O25: =SUM(C25:N25) -> 0
A26: 3 | B26: Base gravable al 0% | C26: 0 | D26: 0 | E26: 0 | F26: 0 | G26: 0 | H26: 0 | I26: 0 | J26: 0 | K26: 0 | L26: 0 | M26: 0 | N26: 0 | O26: =SUM(C26:N26) -> 0
A27: 4 | B27: Base gravable exenta | C27: 0 | D27: 0 | E27: 0 | F27: 0 | G27: 0 | H27: 0 | I27: 0 | J27: 0 | K27: 0 | L27: 0 | M27: 0 | N27: 0 | O27: =SUM(C27:N27) -> 0
B28: Total Base IVA Acreditable | C28: =SUM(C24:C27) -> 303686.29 | D28: =SUM(D24:D27) -> 36577 | E28: =SUM(E24:E27) -> 12764.778 | F28: =SUM(F24:F27) -> 7445.7775 | G28: =SUM(G24:G27) -> 10422.32 | H28: =SUM(H24:H27) -> 159173 | I28: =SUM(I24:I27) -> 15790.578 | J28: =SUM(J24:J27) -> 20983.1 | ... N28: =SUM(N24:N27) -> 19375.174 | O28: =SUM(C28:N28) -> 649556.59
A30: 12 | B30: IVA Acreditable al 16% | C30: =C24*0.16 -> 48589.806 | D30: =D24*0.16 -> 5852.32 | E30: =E24*0.16 -> 2042.3644 | F30: =F24*0.16 -> 1191.3244 | G30: =G24*0.16 -> 1667.5712 | H30: =H24*0.16 -> 25467.68 | I30: 0 | J30: =J24*0.16 -> 3357.296 | K30: =K24*0.16 -> 3129.3684 | L30: =L24*0.16 -> 4091.6118 | M30: =M24*0.16 -> 2913.1914 | N30: =N24*0.16 -> 3100.0278 | O30: =SUM(C30:N30) -> 101402.56
A31: 13 | B31: IVA Acreditable al 8% | C31: =C25*8% -> 0 | D31: =D25*8% -> 0 | E31: =E25*8% -> 0 | F31: =F25*8% -> 0 | G31: =G25*8% -> 0 | H31: =H25*8% -> 0 | I31: =I25*8% -> 0 | J31: =J25*8% -> 0 | ... N31: =N25*8% -> 0 | O31: =SUM(C31:N31) -> 0
A32: 8 | B32: IVA Retenido | C32: 0 | D32: 0 | E32: 0 | F32: 0 | G32: 0 | H32: 0 | I32: 0 | J32: 0 | K32: 0 | L32: 0 | M32: 0 | N32: 0 | O32: =SUM(C32:N32) -> 0
A33: 8 | B33: IVA Retenido Meses Anteriores | C33: 0 | D33: =C32 -> 0 | E33: =D32 -> 0 | F33: =E32 -> 0 | G33: =F32 -> 0 | H33: =G32 -> 0 | I33: =H32 -> 0 | J33: =I32 -> 0 | K33: =J32 -> 0 | ... N33: =M32 -> 0 | O33: =SUM(C33:N33) -> 0
B34: Total IVA Acreditable | C34: =C30+C31-C32+C33 -> 48589.806 | D34: =D30+D31-D32+D33 -> 5852.32 | E34: =E30+E31-E32+E33 -> 2042.3644 | F34: =F30+F31-F32+F33 -> 1191.3244 | G34: =G30+G31-G32+G33 -> 1667.5712 | H34: =H30+H31-H32+H33 -> 25467.68 | I34: =I30+I31-I32+I33 -> 0 | J34: =J30+J31-J32+J33 -> 3357.296 | ... N34: =N30+N31-N32+N33 -> 3100.0278 | O34: =SUM(C34:N34) -> 101402.56
D35: =D37-D32 -> 0
B36: Determinación del IVA | D36: 1
B37: IVA a cargo del periodo | C37: =IF(C21>C34,C21-C34,0) -> 0 | D37: =IF(D21>D34,D21-D34,0) -> 0 | E37: =IF(E21>E34,E21-E34,0) -> 0 | F37: =IF(F21>F34,F21-F34,0) -> 0 | G37: =IF(G21>G34,G21-G34,0) -> 0 | H37: =IF(H21>H34,H21-H34,0) -> 0 | I37: =IF(I21>I34,I21-I34,0) -> 66.896 | J37: =IF(J21>J34,J21-J34,0) -> 0 | ... N37: =IF(N21>N34,N21-N34,0) -> 0 | O37: =SUM(C37:N37) -> 66.896
B38: IVA a favor del periodo | C38: =IF(C21<C34,C34-C21,0) -> 48589.806 | D38: =IF(D21<D34,D34-D21,0) -> 5803.6535 | E38: =IF(E21<E34,E34-E21,0) -> 2042.3644 | F38: =IF(F21<F34,F34-F21,0) -> 1169.366 | G38: =IF(G21<G34,G34-G21,0) -> 1634.4016 | H38: =IF(H21<H34,H34-H21,0) -> 25467.68 | I38: =IF(I21<I34,I34-I21,0) -> 0 | J38: =IF(J21<J34,J34-J21,0) -> 3357.296 | ... N38: =IF(N21<N34,N34-N21,0) -> 3100.0278 | O38: =SUM(C38:N38) -> 101298.77
B39: IVA pendiente por acreditar | C39: 0 | D39: =IF(C41<0,C41*-1,C41) -> 48589.806 | E39: =IF(D41<0,D41*-1,D41) -> 54393.46 | F39: =IF(E41<0,E41*-1,E41) -> 56435.824 | G39: =IF(F41<0,F41*-1,F41) -> 57605.19 | H39: =IF(G41<0,G41*-1,G41) -> 59239.592 | I39: =IF(H41<0,H41*-1,H41) -> 84707.272 | J39: =IF(I41<0,I41*-1,I41) -> 84640.376 | K39: =IF(J41<0,J41*-1,J41) -> 87997.672 | ... N39: =IF(M41<0,M41*-1,M41) -> 98131.844 | O39: =N41 -> 101231.87
B40: IVA a cargo | C40: =IF(C37>C39,C37-C39,0) -> 0 | D40: =IF(D37>D39,D37-D39,0) -> 0 | E40: =IF(E37>E39,E37-E39,0) -> 0 | F40: =IF(F37>F39,F37-F39,0) -> 0 | G40: =IF(G37>G39,G37-G39,0) -> 0 | H40: =IF(H37>H39,H37-H39,0) -> 0 | I40: =IF(I37>I39,I37-I39,0) -> 0 | J40: =IF(J37>J39,J37-J39,0) -> 0 | ... N40: =IF(N37>N39,N37-N39,0) -> 0 | O40: =SUM(C40:N40) -> 0
B41: IVA a favor | C41: =IF(C40=0,IF(C37=0,C38+C39,C39-C37),0) -> 48589.806 | D41: =IF(D40=0,IF(D37=0,D38+D39,D39-D37),0) -> 54393.46 | E41: =IF(E40=0,IF(E37=0,E38+E39,E39-E37),0) -> 56435.824 | F41: =IF(F40=0,IF(F37=0,F38+F39,F39-F37),0) -> 57605.19 | G41: =IF(G40=0,IF(G37=0,G38+G39,G39-G37),0) -> 59239.592 | H41: =IF(H40=0,IF(H37=0,H38+H39,H39-H37),0) -> 84707.272 | I41: =IF(I40=0,IF(I37=0,I38+I39,I39-I37),0) -> 84640.376 | J41: =IF(J40=0,IF(J37=0,J38+J39,J39-J37),0) -> 87997.672 | ... N41: =IF(N40=0,IF(N37=0,N38+N39,N39-N37),0) -> 101231.87

Sheet T ISR
A1: ENERO | F1: FEBRERO
A2: Límite inferior | B2: Límite superior | C2: Cuota fija | D2: Por ciento para aplicarse sobre | F2: Límite inferior | G2: Límite superior | H2: Cuota fija | I2: Por ciento para aplicarse sobre
D3: el excedente del límite inferior | I3: el excedente del límite inferior
A4: $ | B4: $ | C4: $ | D4: % | F4: $ | G4: $ | H4: $ | I4: %
A5: 0.01 | B5: 746.04 | C5: 0 | D5: 0.0192 | F5: 0.01 | G5: 1492.08 | H5: 0 | I5: 0.0192
A6: 746.05 | B6: 6332.05 | C6: 14.32 | D6: 0.064 | F6: 1492.09 | G6: 12664.1 | H6: 28.64 | I6: 0.064
A7: 6332.06 | B7: 11128.01 | C7: 371.83 | D7: 0.1088 | F7: 12664.11 | G7: 22256.02 | H7: 743.66 | I7: 0.1088
A8: 11128.02 | B8: 12935.82 | C8: 893.63 | D8: 0.16 | F8: 22256.03 | G8: 25871.64 | H8: 1787.26 | I8: 0.16
A9: 12935.83 | B9: 15487.71 | C9: 1182.88 | D9: 0.1792 | F9: 25871.65 | G9: 30975.42 | H9: 2365.76 | I9: 0.1792
A10: 15487.72 | B10: 31236.49 | C10: 1640.18 | D10: 0.2136 | F10: 30975.43 | G10: 62472.98 | H10: 3280.36 | I10: 0.2136
A11: 31236.5 | B11: 49233 | C11: 5004.12 | D11: 0.2352 | F11: 62472.99 | G11: 98466 | H11: 10008.24 | I11: 0.2352
A12: 49233.01 | B12: 93993.9 | C12: 9236.89 | D12: 0.3 | F12: 98466.01 | G12: 187987.8 | H12: 18473.78 | I12: 0.3
A13: 93993.91 | B13: 125325.2 | C13: 22665.17 | D13: 0.32 | F13: 187987.81 | G13: 250650.4 | H13: 45330.34 | I13: 0.32
A14: 125325.21 | B14: 375975.61 | C14: 32691.18 | D14: 0.34 | F14: 250650.41 | G14: 751951.22 | H14: 65382.36 | I14: 0.34
A15: 375975.62 | B15: En adelante | C15: 117912.32 | D15: 0.35 | F15: 751951.23 | G15: En adelante | H15: 235824.64 | I15: 0.35
A17: MARZO | F17: ABRIL
A18: Límite inferior | B18: Límite superior | C18: Cuota fija | D18: Por ciento para aplicarse sobre | F18: Límite inferior | G18: Límite superior | H18: Cuota fija | I18: Por ciento para aplicarse sobre
D19: el excedente del límite inferior | I19: el excedente del límite inferior
A20: $ | B20: $ | C20: $ | D20: % | F20: $ | G20: $ | H20: $ | I20: %
A21: 0.01 | B21: 2238.12 | C21: 0 | D21: 0.0192 | F21: 0.01 | G21: 2984.16 | H21: 0 | I21: 0.0192
A22: 2238.13 | B22: 18996.15 | C22: 42.96 | D22: 0.064 | F22: 2984.17 | G22: 25328.2 | H22: 57.28 | I22: 0.064
A23: 18996.16 | B23: 33384.03 | C23: 1115.49 | D23: 0.1088 | F23: 25328.21 | G23: 44512.04 | H23: 1487.32 | I23: 0.1088
A24: 33384.04 | B24: 38807.46 | C24: 2680.89 | D24: 0.16 | F24: 44512.05 | G24: 51743.28 | H24: 3574.52 | I24: 0.16
A25: 38807.47 | B25: 46463.13 | C25: 3548.64 | D25: 0.1792 | F25: 51743.29 | G25: 61950.84 | H25: 4731.52 | I25: 0.1792
A26: 46463.14 | B26: 93709.47 | C26: 4920.54 | D26: 0.2136 | F26: 61950.85 | G26: 124945.96 | H26: 6560.72 | I26: 0.2136
A27: 93709.48 | B27: 147699 | C27: 15012.36 | D27: 0.2352 | F27: 124945.97 | G27: 196932 | H27: 20016.48 | I27: 0.2352
A28: 147699.01 | B28: 281981.7 | C28: 27710.67 | D28: 0.3 | F28: 196932.01 | G28: 375975.6 | H28: 36947.56 | I28: 0.3
A29: 281981.71 | B29: 375975.6 | C29: 67995.51 | D29: 0.32 | F29: 375975.61 | G29: 501300.8 | H29: 90660.68 | I29: 0.32
A30: 375975.61 | B30: 1127926.8 | C30: 98073.54 | D30: 0.34 | F30: 501300.81 | G30: 1503902.4 | H30: 130764.72 | I30: 0.34
A31: 1127926.8 | B31: En adelante | C31: 353736.96 | D31: 0.35 | F31: 1503902.4 | G31: En adelante | H31: 471649.28 | I31: 0.35
A33: MAYO | F33: JUNIO
A34: Límite inferior | B34: Límite superior | C34: Cuota fija | D34: Por ciento para aplicarse sobre | F34: Límite inferior | G34: Límite superior | H34: Cuota fija | I34: Por ciento para aplicarse sobre
D35: el excedente del límite inferior | I35: el excedente del límite inferior
A36: $ | B36: $ | C36: $ | D36: % | F36: $ | G36: $ | H36: $ | I36: %
A37: 0.01 | B37: 3730.2 | C37: 0 | D37: 0.0192 | F37: 0.01 | G37: 4476.24 | H37: 0 | I37: 0.0192
A38: 3730.21 | B38: 31660.25 | C38: 71.6 | D38: 0.064 | F38: 4476.25 | G38: 37992.3 | H38: 85.92 | I38: 0.064
A39: 31660.26 | B39: 55640.05 | C39: 1859.15 | D39: 0.1088 | F39: 37992.31 | G39: 66768.06 | H39: 2230.98 | I39: 0.1088
A40: 55640.06 | B40: 64679.1 | C40: 4468.15 | D40: 0.16 | F40: 66768.07 | G40: 77614.92 | H40: 5361.78 | I40: 0.16
A41: 64679.11 | B41: 77438.55 | C41: 5914.4 | D41: 0.1792 | F41: 77614.93 | G41: 92926.26 | H41: 7097.28 | I41: 0.1792
A42: 77438.56 | B42: 156182.45 | C42: 8200.9 | D42: 0.2136 | F42: 92926.27 | G42: 187418.94 | H42: 9841.08 | I42: 0.2136
...

Sheet ING
A1: MES | C1: FECHA DE EMISION | D1: FECHA COBRO | E1: Tipo Ingreso (tasa de iva) | F1: FOLIO | G1: CLIENTE | H1: RFC | J1: IMPORTE | K1: IVA | L1: IVA RETENIDO | M1: ISR RETENIDO | N1: TOTAL | O1: codigo postal | P1: REGIMEN
A2: =IF(D2>0,MONTH(D2),0) -> 1 | B2: =VLOOKUP(A2,[1]Hoja3!$C$3:$D$14,2,FALSE) -> ENERO | C2: 45302 | D2: 45302 | E2: PG | G2: MARIELA OLMOS GAONA | H2: =IF(G2="EFREN ABUNDEZ REYNA","AURE7306187IA",IF(G2="LUIS ALEJANDRO HERNANDEZ REYNA","HERL850705AL2",IF(G2="ANA BEATRIZ ESTRADA ARGOTE","EAAA860701UP2",IF(G2="SERGIO ROMERO DURAN","RODS620908QAA",IF(G2="MARIELA OLMOS GAONA","OOGM010703NX1",IF(G2="LUCIANO MIJAIL ORTEGA MUÑOZ","OEML881105IK2",IF(G2="GUSTAVO HUMBERTO VELAZCO GALVAN","VEGG9211019T1",IF(G2="JESUS AGUSTIN VELAZQUEZ FLORES","VEFJ900303M65",IF(G2="KARLA ESTEFANIA SALAZAR FLORES","SAFK9807277N1",IF(G2="ANGEL TERRAZAS MONROY","TEMA7105035N4")))))))))) -> OOGM010703NX1 | I2: =+B2 -> ENERO | J2: 13500 | K2: 0 | N2: =+J2+K2-L2-M2 -> 13500 | O2: =IF(G2="EFREN ABUNDEZ REYNA","37295",IF(G2="LUIS ALEJANDRO HERNANDEZ REYNA","HERL850705AL2",IF(G2="ANA BEATRIZ ESTRADA ARGOTE","EAAA860701UP2",IF(G2="SERGIO ROMERO DURAN","RODS620908QAA",IF(G2="MARIELA OLMOS GAONA","37675",IF(G2="LUCIANO MIJAIL ORTEGA MUÑOZ","37297",IF(G2="GUSTAVO HUMBERTO VELAZCO GALVAN","VEGG9211019T1",IF(G2="JESUS AGUSTIN VELAZQUEZ FLORES","VEFJ900303M65",IF(G2="KARLA ESTEFANIA SALAZAR FLORES","SAFK9807277N1",IF(G2="ANGEL TERRAZAS MONROY","TEMA7105035N4")))))))))) -> 37675 | P2: =IF(G2="EFREN ABUNDEZ REYNA","PFAEP",IF(G2="LUIS ALEJANDRO HERNANDEZ REYNA","HERL850705AL2",IF(G2="ANA BEATRIZ ESTRADA ARGOTE","EAAA860701UP2",IF(G2="SERGIO ROMERO DURAN","RODS620908QAA",IF(G2="MARIELA OLMOS GAONA","RESICO",IF(G2="LUCIANO MIJAIL ORTEGA MUÑOZ","RIF",IF(G2="GUSTAVO HUMBERTO VELAZCO GALVAN","VEGG9211019T1",IF(G2="JESUS AGUSTIN VELAZQUEZ FLORES","VEFJ900303M65",IF(G2="KARLA ESTEFANIA SALAZAR FLORES","SAFK9807277N1",IF(G2="ANGEL TERRAZAS MONROY","TEMA7105035N4")))))))))) -> RESICO
A3: =IF(D3>0,MONTH(D3),0) -> 1 | B3: =VLOOKUP(A3,[1]Hoja3!$C$3:$D$14,2,FALSE) -> ENERO | C3: 45302 | D3: 45302 | E3: 16 | G3: MARIELA OLMOS GAONA | H3: =IF(G3="EFREN ABUNDEZ REYNA","AURE7306187IA",IF(G3="LUIS ALEJANDRO HERNANDEZ REYNA","HERL850705AL2",IF(G3="ANA BEATRIZ ESTRADA ARGOTE","EAAA860701UP2",IF(G3="SERGIO ROMERO DURAN","RODS620908QAA",IF(G3="MARIELA OLMOS GAONA","OOGM010703NX1",IF(G3="LUCIANO MIJAIL ORTEGA MUÑOZ","OEML881105IK2",IF(G3="GUSTAVO HUMBERTO VELAZCO GALVAN","VEGG9211019T1",IF(G3="JESUS AGUSTIN VELAZQUEZ FLORES","VEFJ900303M65",IF(G3="KARLA ESTEFANIA SALAZAR FLORES","SAFK9807277N1",IF(G3="ANGEL TERRAZAS MONROY","TEMA7105035N4")))))))))) -> OOGM010703NX1 | I3: =+B3 -> ENERO | J3: 5850 | K3: 0 | N3: =+J3+K3-L3-M3 -> 5850 | O3: =IF(G3="EFREN ABUNDEZ REYNA","37295",IF(G3="LUIS ALEJANDRO HERNANDEZ REYNA","HERL850705AL2",IF(G3="ANA BEATRIZ ESTRADA ARGOTE","EAAA860701UP2",IF(G3="SERGIO ROMERO DURAN","RODS620908QAA",IF(G3="MARIELA OLMOS GAONA","37675",IF(G3="LUCIANO MIJAIL ORTEGA MUÑOZ","37297",IF(G3="GUSTAVO HUMBERTO VELAZCO GALVAN","VEGG9211019T1",IF(G3="JESUS AGUSTIN VELAZQUEZ FLORES","VEFJ900303M65",IF(G3="KARLA ESTEFANIA SALAZAR FLORES","SAFK9807277N1",IF(G3="ANGEL TERRAZAS MONROY","TEMA7105035N4")))))))))) -> 37675 | P3: =IF(G3="EFREN ABUNDEZ REYNA","PFAEP",IF(G3="LUIS ALEJANDRO HERNANDEZ REYNA","HERL850705AL2",IF(G3="ANA BEATRIZ ESTRADA ARGOTE","EAAA860701UP2",IF(G3="SERGIO ROMERO DURAN","RODS620908QAA",IF(G3="MARIELA OLMOS GAONA","RESICO",IF(G3="LUCIANO MIJAIL ORTEGA MUÑOZ","RIF",IF(G3="GUSTAVO HUMBERTO VELAZCO GALVAN","VEGG9211019T1",IF(G3="JESUS AGUSTIN VELAZQUEZ FLORES","VEFJ900303M65",IF(G3="KARLA ESTEFANIA SALAZAR FLORES","SAFK9807277N1",IF(G3="ANGEL TERRAZAS MONROY","TEMA7105035N4")))))))))) -> RESICO
A4: =IF(D4>0,MONTH(D4),0) -> 1 | B4: =VLOOKUP(A4,[1]Hoja3!$C$3:$D$14,2,FALSE) -> ENERO | C4: 45302 | D4: 45302 | G4: EFREN ABUNDEZ REYNA | H4: =IF(G4="EFREN ABUNDEZ REYNA","AURE7306187IA",IF(G4="LUIS ALEJANDRO HERNANDEZ REYNA","HERL850705AL2",IF(G4="ANA BEATRIZ ESTRADA ARGOTE","EAAA860701UP2",IF(G4="SERGIO ROMERO DURAN","RODS620908QAA",IF(G4="MARIELA OLMOS GAONA","OOGM010703NX1",IF(G4="LUCIANO MIJAIL ORTEGA MUÑOZ","OEML881105IK2",IF(G4="GUSTAVO HUMBERTO VELAZCO GALVAN","VEGG9211019T1",IF(G4="JESUS AGUSTIN VELAZQUEZ FLORES","VEFJ900303M65",IF(G4="KARLA ESTEFANIA SALAZAR FLORES","SAFK9807277N1",IF(G4="ANGEL TERRAZAS MONROY","TEMA7105035N4")))))))))) -> AURE7306187IA | I4: =+B4 -> ENERO | J4: 1090 | K4: 0 | N4: =+J4+K4-L4-M4 -> 1090 | O4: =IF(G4="EFREN ABUNDEZ REYNA","37295",IF(G4="LUIS ALEJANDRO HERNANDEZ REYNA","HERL850705AL2",IF(G4="ANA BEATRIZ ESTRADA ARGOTE","EAAA860701UP2",IF(G4="SERGIO ROMERO DURAN","RODS620908QAA",IF(G4="MARIELA OLMOS GAONA","37675",IF(G4="LUCIANO MIJAIL ORTEGA MUÑOZ","37297",IF(G4="GUSTAVO HUMBERTO VELAZCO GALVAN","VEGG9211019T1",IF(G4="JESUS AGUSTIN VELAZQUEZ FLORES","VEFJ900303M65",IF(G4="KARLA ESTEFANIA SALAZAR FLORES","SAFK9807277N1",IF(G4="ANGEL TERRAZAS MONROY","TEMA7105035N4")))))))))) -> 37295 | P4: =IF(G4="EFREN ABUNDEZ REYNA","PFAEP",IF(G4="LUIS ALEJANDRO HERNANDEZ REYNA","HERL850705AL2",IF(G4="ANA BEATRIZ ESTRADA ARGOTE","EAAA860701UP2",IF(G4="SERGIO ROMERO DURAN","RODS620908QAA",IF(G4="MARIELA OLMOS GAONA","RESICO",IF(G4="LUCIANO MIJAIL ORTEGA MUÑOZ","RIF",IF(G4="GUSTAVO HUMBERTO VELAZCO GALVAN","VEGG9211019T1",IF(G4="JESUS AGUSTIN VELAZQUEZ FLORES","VEFJ900303M65",IF(G4="KARLA ESTEFANIA SALAZAR FLORES","SAFK9807277N1",IF(G4="ANGEL TERRAZAS MONROY","TEMA7105035N4")))))))))) -> PFAEP
A5: =IF(D5>0,MONTH(D5),0) -> 1 | B5: =VLOOKUP(A5,[1]Hoja3!$C$3:$D$14,2,FALSE) -> ENERO | C5: 45302 | D5: 45302 | G5: EFREN ABUNDEZ REYNA | H5: =IF(G5="EFREN ABUNDEZ REYNA","AURE7306187IA",IF(G5="LUIS ALEJANDRO HERNANDEZ REYNA","HERL850705AL2",IF(G5="ANA BEATRIZ ESTRADA ARGOTE","EAAA860701UP2",IF(G5="SERGIO ROMERO DURAN","RODS620908QAA",IF(G5="MARIELA OLMOS GAONA","OOGM010703NX1",IF(G5="LUCIANO MIJAIL ORTEGA MUÑOZ","OEML881105IK2",IF(G5="GUSTAVO HUMBERTO VELAZCO GALVAN","VEGG9211019T1",IF(G5="JESUS AGUSTIN VELAZQUEZ FLORES","VEFJ900303M65",IF(G5="KARLA ESTEFANIA SALAZAR FLORES","SAFK9807277N1",IF(G5="ANGEL TERRAZAS MONROY","TEMA7105035N4")))))))))) -> AURE7306187IA | I5: =+B5 -> ENERO | J5: 1090 | K5: 0 | N5: =+J5+K5-L5-M5 -> 1090 | O5: =IF(G5="EFREN ABUNDEZ REYNA","37295",IF(G5="LUIS ALEJANDRO HERNANDEZ REYNA","HERL850705AL2",IF(G5="ANA BEATRIZ ESTRADA ARGOTE","EAAA860701UP2",IF(G5="SERGIO ROMERO DURAN","RODS620908QAA",IF(G5="MARIELA OLMOS GAONA","37675",IF(G5="LUCIANO MIJAIL ORTEGA MUÑOZ","37297",IF(G5="GUSTAVO HUMBERTO VELAZCO GALVAN","VEGG9211019T1",IF(G5="JESUS AGUSTIN VELAZQUEZ FLORES","VEFJ900303M65",IF(G5="KARLA ESTEFANIA SALAZAR FLORES","SAFK9807277N1",IF(G5="ANGEL TERRAZAS MONROY","TEMA7105035N4")))))))))) -> 37295 | P5: =IF(G5="EFREN ABUNDEZ REYNA","PFAEP",IF(G5="LUIS ALEJANDRO HERNANDEZ REYNA","HERL850705AL2",IF(G5="ANA BEATRIZ ESTRADA ARGOTE","EAAA860701UP2",IF(G5="SERGIO ROMERO DURAN","RODS620908QAA",IF(G5="MARIELA OLMOS GAONA","RESICO",IF(G5="LUCIANO MIJAIL ORTEGA MUÑOZ","RIF",IF(G5="GUSTAVO HUMBERTO VELAZCO GALVAN","VEGG9211019T1",IF(G5="JESUS AGUSTIN VELAZQUEZ FLORES","VEFJ900303M65",IF(G5="KARLA ESTEFANIA SALAZAR FLORES","SAFK9807277N1",IF(G5="ANGEL TERRAZAS MONROY","TEMA7105035N4")))))))))) -> PFAEP
A6: =IF(D6>0,MONTH(D6),0) -> 1 | B6: =VLOOKUP(A6,[1]Hoja3!$C$3:$D$14,2,FALSE) -> ENERO | C6: 45309 | D6: 45309 | G6: CAJA POPULAR MEXICANA | H6: CPM960127M3A | I6: =+B6 -> ENERO | J6: 510 | K6: =+J6*0.16 -> 81.6 | N6: =+J6+K6-L6-M6 -> 591.6 | O6: 37004 | P6: moral no lucrativa | Q6: hedj124791234@gmail.com
A7: =IF(D7>0,MONTH(D7),0) -> 1 | B7: =VLOOKUP(A7,[1]Hoja3!$C$3:$D$14,2,FALSE) -> ENERO | C7: 45309 | D7: 45309 | G7: MARIELA OLMOS GAONA | H7: =IF(G7="EFREN ABUNDEZ REYNA","AURE7306187IA",IF(G7="LUIS ALEJANDRO HERNANDEZ REYNA","HERL850705AL2",IF(G7="ANA BEATRIZ ESTRADA ARGOTE","EAAA860701UP2",IF(G7="SERGIO ROMERO DURAN","RODS620908QAA",IF(G7="MARIELA OLMOS GAONA","OOGM010703NX1",IF(G7="LUCIANO MIJAIL ORTEGA MUÑOZ","OEML881105IK2",IF(G7="GUSTAVO HUMBERTO VELAZCO GALVAN","VEGG9211019T1",IF(G7="JESUS AGUSTIN VELAZQUEZ FLORES","VEFJ900303M65",IF(G7="KARLA ESTEFANIA SALAZAR FLORES","SAFK9807277N1",IF(G7="ANGEL TERRAZAS MONROY","TEMA7105035N4")))))))))) -> OOGM010703NX1 | I7: =+B7 -> ENERO | J7: 7025 | K7: 0 | N7: =+J7+K7-L7-M7 -> 7025 | O7: =IF(G7="EFREN ABUNDEZ REYNA","37295",IF(G7="LUIS ALEJANDRO HERNANDEZ REYNA","HERL850705AL2",IF(G7="ANA BEATRIZ ESTRADA ARGOTE","EAAA860701UP2",IF(G7="SERGIO ROMERO DURAN","RODS620908QAA",IF(G7="MARIELA OLMOS GAONA","37675",IF(G7="LUCIANO MIJAIL ORTEGA MUÑOZ","37297",IF(G7="GUSTAVO HUMBERTO VELAZCO GALVAN","VEGG9211019T1",IF(G7="JESUS AGUSTIN VELAZQUEZ FLORES","VEFJ900303M65",IF(G7="KARLA ESTEFANIA SALAZAR FLORES","SAFK9807277N1",IF(G7="ANGEL TERRAZAS MONROY","TEMA7105035N4")))))))))) -> 37675 | P7: =IF(G7="EFREN ABUNDEZ REYNA","PFAEP",IF(G7="LUIS ALEJANDRO HERNANDEZ REYNA","HERL850705AL2",IF(G7="ANA BEATRIZ ESTRADA ARGOTE","EAAA860701UP2",IF(G7="SERGIO ROMERO DURAN","RODS620908QAA",IF(G7="MARIELA OLMOS GAONA","RESICO",IF(G7="LUCIANO MIJAIL ORTEGA MUÑOZ","RIF",IF(G7="GUSTAVO HUMBERTO VELAZCO GALVAN","VEGG9211019T1",IF(G7="JESUS AGUSTIN VELAZQUEZ FLORES","VEFJ900303M65",IF(G7="KARLA ESTEFANIA SALAZAR FLORES","SAFK9807277N1",IF(G7="ANGEL TERRAZAS MONROY","TEMA7105035N4")))))))))) -> RESICO
A8: =IF(D8>0,MONTH(D8),0) -> 1 | B8: =VLOOKUP(A8,[1]Hoja3!$C$3:$D$14,2,FALSE) -> ENERO | C8: 45309 | D8: 45309 | G8: EFREN ABUNDEZ REYNA | H8: =IF(G8="EFREN ABUNDEZ REYNA","AURE7306187IA",IF(G8="LUIS ALEJANDRO HERNANDEZ REYNA","HERL850705AL2",IF(G8="ANA BEATRIZ ESTRADA ARGOTE","EAAA860701UP2",IF(G8="SERGIO ROMERO DURAN","RODS620908QAA",IF(G8="MARIELA OLMOS GAONA","OOGM010703NX1",IF(G8="LUCIANO MIJAIL ORTEGA MUÑOZ","OEML881105IK2",IF(G8="GUSTAVO HUMBERTO VELAZCO GALVAN","VEGG9211019T1",IF(G8="JESUS AGUSTIN VELAZQUEZ FLORES","VEFJ900303M65",IF(G8="KARLA ESTEFANIA SALAZAR FLORES","SAFK9807277N1",IF(G8="ANGEL TERRAZAS MONROY","TEMA7105035N4")))))))))) -> AURE7306187IA | I8: =+B8 -> ENERO | J8: 1977 | K8: 0 | N8: =+J8+K8-L8-M8 -> 1977 | O8: =IF(G8="EFREN ABUNDEZ REYNA","37295",IF(G8="LUIS ALEJANDRO HERNANDEZ REYNA","HERL850705AL2",IF(G8="ANA BEATRIZ ESTRADA ARGOTE","EAAA860701UP2",IF(G8="SERGIO ROMERO DURAN","RODS620908QAA",IF(G8="MARIELA OLMOS GAONA","37675",IF(G8="LUCIANO MIJAIL ORTEGA MUÑOZ","37297",IF(G8="GUSTAVO HUMBERTO VELAZCO GALVAN","VEGG9211019T1",IF(G8="JESUS AGUSTIN VELAZQUEZ FLORES","VEFJ900303M65",IF(G8="KARLA ESTEFANIA SALAZAR FLORES","SAFK9807277N1",IF(G8="ANGEL TERRAZAS MONROY","TEMA7105035N4")))))))))) -> 37295 | P8: =IF(G8="EFREN ABUNDEZ REYNA","PFAEP",IF(G8="LUIS ALEJANDRO HERNANDEZ REYNA","HERL850705AL2",IF(G8="ANA BEATRIZ ESTRADA ARGOTE","EAAA860701UP2",IF(G8="SERGIO ROMERO DURAN","RODS620908QAA",IF(G8="MARIELA OLMOS GAONA","RESICO",IF(G8="LUCIANO MIJAIL ORTEGA MUÑOZ","RIF",IF(G8="GUSTAVO HUMBERTO VELAZCO GALVAN","VEGG9211019T1",IF(G8="JESUS AGUSTIN VELAZQUEZ FLORES","VEFJ900303M65",IF(G8="KARLA ESTEFANIA SALAZAR FLORES","SAFK9807277N1",IF(G8="ANGEL TERRAZAS MONROY","TEMA7105035N4")))))))))) -> PFAEP
A9: =IF(D9>0,MONTH(D9),0) -> 1 | B9: =VLOOKUP(A9,[1]Hoja3!$C$3:$D$14,2,FALSE) -> ENERO | C9: 45309 | D9: 45309 | G9: EFREN ABUNDEZ REYNA | H9: =IF(G9="EFREN ABUNDEZ REYNA","AURE7306187IA",IF(G9="LUIS ALEJANDRO HERNANDEZ REYNA","HERL850705AL2",IF(G9="ANA BEATRIZ ESTRADA ARGOTE","EAAA860701UP2",IF(G9="SERGIO ROMERO DURAN","RODS620908QAA",IF(G9="MARIELA OLMOS GAONA","OOGM010703NX1",IF(G9="LUCIANO MIJAIL ORTEGA MUÑOZ","OEML881105IK2",IF(G9="GUSTAVO HUMBERTO VELAZCO GALVAN","VEGG9211019T1",IF(G9="JESUS AGUSTIN VELAZQUEZ FLORES","VEFJ900303M65",IF(G9="KARLA ESTEFANIA SALAZAR FLORES","SAFK9807277N1",IF(G9="ANGEL TERRAZAS MONROY","TEMA7105035N4")))))))))) -> AURE7306187IA | I9: =+B9 -> ENERO | J9: 1977 | K9: 0 | N9: =+J9+K9-L9-M9 -> 1977 | O9: =IF(G9="EFREN ABUNDEZ REYNA","37295",IF(G9="LUIS ALEJANDRO HERNANDEZ REYNA","HERL850705AL2",IF(G9="ANA BEATRIZ ESTRADA ARGOTE","EAAA860701UP2",IF(G9="SERGIO ROMERO DURAN","RODS620908QAA",IF(G9="MARIELA OLMOS GAONA","37675",IF(G9="LUCIANO MIJAIL ORTEGA MUÑOZ","37297",IF(G9="GUSTAVO HUMBERTO VELAZCO GALVAN","VEGG9211019T1",IF(G9="JESUS AGUSTIN VELAZQUEZ FLORES","VEFJ900303M65",IF(G9="KARLA ESTEFANIA SALAZAR FLORES","SAFK9807277N1",IF(G9="ANGEL TERRAZAS MONROY","TEMA7105035N4")))))))))) -> 37295 | P9: =IF(G9="EFREN ABUNDEZ REYNA","PFAEP",IF(G9="LUIS ALEJANDRO HERNANDEZ REYNA","HERL850705AL2",IF(G9="ANA BEATRIZ ESTRADA ARGOTE","EAAA860701UP2",IF(G9="SERGIO ROMERO DURAN","RODS620908QAA",IF(G9="MARIELA OLMOS GAONA","RESICO",IF(G9="LUCIANO MIJAIL ORTEGA MUÑOZ","RIF",IF(G9="GUSTAVO HUMBERTO VELAZCO GALVAN","VEGG9211019T1",IF(G9="JESUS AGUSTIN VELAZQUEZ FLORES","VEFJ900303M65",IF(G9="KARLA ESTEFANIA SALAZAR FLORES","SAFK9807277N1",IF(G9="ANGEL TERRAZAS MONROY","TEMA7105035N4")))))))))) -> PFAEP
A10: =IF(D10>0,MONTH(D10),0) -> 1 | B10: =VLOOKUP(A10,[1]Hoja3!$C$3:$D$14,2,FALSE) -> ENERO | C10: 45316 | D10: 45316 | G10: MARIELA OLMOS GAONA | H10: =IF(G10="EFREN ABUNDEZ REYNA","AURE7306187IA",IF(G10="LUIS ALEJANDRO HERNANDEZ REYNA","HERL850705AL2",IF(G10="ANA BEATRIZ ESTRADA ARGOTE","EAAA860701UP2",IF(G10="SERGIO ROMERO DURAN","RODS620908QAA",IF(G10="MARIELA OLMOS GAONA","OOGM010703NX1",IF(G10="LUCIANO MIJAIL ORTEGA MUÑOZ","OEML881105IK2",IF(G10="GUSTAVO HUMBERTO VELAZCO GALVAN","VEGG9211019T1",IF(G10="JESUS AGUSTIN VELAZQUEZ FLORES","VEFJ900303M65",IF(G10="KARLA ESTEFANIA SALAZAR FLORES","SAFK9807277N1",IF(G10="ANGEL TERRAZAS MONROY","TEMA7105035N4")))))))))) -> OOGM010703NX1 | I10: =+B10 -> ENERO | J10: 6990 | K10: 0 | N10: =+J10+K10-L10-M10 -> 6990 | O10: =IF(G10="EFREN ABUNDEZ REYNA","37295",IF(G10="LUIS ALEJANDRO HERNANDEZ REYNA","HERL850705AL2",IF(G10="ANA BEATRIZ ESTRADA ARGOTE","EAAA860701UP2",IF(G10="SERGIO ROMERO DURAN","RODS620908QAA",IF(G10="MARIELA OLMOS GAONA","37675",IF(G10="LUCIANO MIJAIL ORTEGA MUÑOZ","37297",IF(G10="GUSTAVO HUMBERTO VELAZCO GALVAN","VEGG9211019T1",IF(G10="JESUS AGUSTIN VELAZQUEZ FLORES","VEFJ900303M65",IF(G10="KARLA ESTEFANIA SALAZAR FLORES","SAFK9807277N1",IF(G10="ANGEL TERRAZAS MONROY","TEMA7105035N4")))))))))) -> 37675 | P10: =IF(G10="EFREN ABUNDEZ REYNA","PFAEP",IF(G10="LUIS ALEJANDRO HERNANDEZ REYNA","HERL850705AL2",IF(G10="ANA BEATRIZ ESTRADA ARGOTE","EAAA860701UP2",IF(G10="SERGIO ROMERO DURAN","RODS620908QAA",IF(G10="MARIELA OLMOS GAONA","RESICO",IF(G10="LUCIANO MIJAIL ORTEGA MUÑOZ","RIF",IF(G10="GUSTAVO HUMBERTO VELAZCO GALVAN","VEGG9211019T1",IF(G10="JESUS AGUSTIN VELAZQUEZ FLORES","VEFJ900303M65",IF(G10="KARLA ESTEFANIA SALAZAR FLORES","SAFK9807277N1",IF(G10="ANGEL TERRAZAS MONROY","TEMA7105035N4")))))))))) -> RESICO
A11: =IF(D11>0,MONTH(D11),0) -> 1 | B11: =VLOOKUP(A11,[1]Hoja3!$C$3:$D$14,2,FALSE) -> ENERO | C11: 45316 | D11: 45316 | G11: EFREN ABUNDEZ REYNA | H11: =IF(G11="EFREN ABUNDEZ REYNA","AURE7306187IA",IF(G11="LUIS ALEJANDRO HERNANDEZ REYNA","HERL850705AL2",IF(G11="ANA BEATRIZ ESTRADA ARGOTE","EAAA860701UP2",IF(G11="SERGIO ROMERO DURAN","RODS620908QAA",IF(G11="MARIELA OLMOS GAONA","OOGM010703NX1",IF(G11="LUCIANO MIJAIL ORTEGA MUÑOZ","OEML881105IK2",IF(G11="GUSTAVO HUMBERTO VELAZCO GALVAN","VEGG9211019T1",IF(G11="JESUS AGUSTIN VELAZQUEZ FLORES","VEFJ900303M65",IF(G11="KARLA ESTEFANIA SALAZAR FLORES","SAFK9807277N1",IF(G11="ANGEL TERRAZAS MONROY","TEMA7105035N4")))))))))) -> AURE7306187IA | I11: =+B11 -> ENERO | J11: 1615 | K11: 0 | N11: =+J11+K11-L11-M11 -> 1615 | O11: =IF(G11="EFREN ABUNDEZ REYNA","37295",IF(G11="LUIS ALEJANDRO HERNANDEZ REYNA","HERL850705AL2",IF(G11="ANA BEATRIZ ESTRADA ARGOTE","EAAA860701UP2",IF(G11="SERGIO ROMERO DURAN","RODS620908QAA",IF(G11="MARIELA OLMOS GAONA","37675",IF(G11="LUCIANO MIJAIL ORTEGA MUÑOZ","37297",IF(G11="GUSTAVO HUMBERTO VELAZCO GALVAN","VEGG9211019T1",IF(G11="JESUS AGUSTIN VELAZQUEZ FLORES","VEFJ900303M65",IF(G11="KARLA ESTEFANIA SALAZAR FLORES","SAFK9807277N1",IF(G11="ANGEL TERRAZAS MONROY","TEMA7105035N4")))))))))) -> 37295 | P11: =IF(G11="EFREN ABUNDEZ REYNA","PFAEP",IF(G11="LUIS ALEJANDRO HERNANDEZ REYNA","HERL850705AL2",IF(G11="ANA BEATRIZ ESTRADA ARGOTE","EAAA860701UP2",IF(G11="SERGIO ROMERO DURAN","RODS620908QAA",IF(G11="MARIELA OLMOS GAONA","RESICO",IF(G11="LUCIANO MIJAIL ORTEGA MUÑOZ","RIF",IF(G11="GUSTAVO HUMBERTO VELAZCO GALVAN","VEGG9211019T1",IF(G11="JESUS AGUSTIN VELAZQUEZ FLORES","VEFJ900303M65",IF(G11="KARLA ESTEFANIA SALAZAR FLORES","SAFK9807277N1",IF(G11="ANGEL TERRAZAS MONROY","TEMA7105035N4")))))))))) -> PFAEP
A12: =IF(D12>0,MONTH(D12),0) -> 1 | B12: =VLOOKUP(A12,[1]Hoja3!$C$3:$D$14,2,FALSE) -> ENERO | C12: 45321 | D12: 45321 | G12: IITS IDENTIFICATION E INFORMATION TRANSPORT SYSTEMS | H12: IIE101203RU0 | I12: =+B12 -> ENERO | J12: 219 | K12: =+J12*0.16 -> 35.04 | N12: =+J12+K12-L12-M12 -> 254.04 | O12: 11289 | P12: MORAL | Q12: elopez@iits.com.mx | R12: T.D.
A13: =IF(D13>0,MONTH(D13),0) -> 1 | B13: =VLOOKUP(A13,[1]Hoja3!$C$3:$D$14,2,FALSE) -> ENERO | C13: 45321 | D13: 45321 | G13: MARIELA OLMOS GAONA | H13: =IF(G13="EFREN ABUNDEZ REYNA","AURE7306187IA",IF(G13="LUIS ALEJANDRO HERNANDEZ REYNA","HERL850705AL2",IF(G13="ANA BEATRIZ ESTRADA ARGOTE","EAAA860701UP2",IF(G13="SERGIO ROMERO DURAN","RODS620908QAA",IF(G13="MARIELA OLMOS GAONA","OOGM010703NX1",IF(G13="LUCIANO MIJAIL ORTEGA MUÑOZ","OEML881105IK2",IF(G13="GUSTAVO HUMBERTO VELAZCO GALVAN","VEGG9211019T1",IF(G13="JESUS AGUSTIN VELAZQUEZ FLORES","VEFJ900303M65",IF(G13="KARLA ESTEFANIA SALAZAR FLORES","SAFK9807277N1",IF(G13="ANGEL TERRAZAS MONROY","TEMA7105035N4")))))))))) -> OOGM010703NX1 | I13: =+B13 -> ENERO | J13: 8155 | K13: 0 | N13: =+J13+K13-L13-M13 -> 8155 | O13: =IF(G13="EFREN ABUNDEZ REYNA","37295",IF(G13="LUIS ALEJANDRO HERNANDEZ REYNA","HERL850705AL2",IF(G13="ANA BEATRIZ ESTRADA ARGOTE","EAAA860701UP2",IF(G13="SERGIO ROMERO DURAN","RODS620908QAA",IF(G13="MARIELA OLMOS GAONA","37675",IF(G13="LUCIANO MIJAIL ORTEGA MUÑOZ","37297",IF(G13="GUSTAVO HUMBERTO VELAZCO GALVAN","VEGG9211019T1",IF(G13="JESUS AGUSTIN VELAZQUEZ FLORES","VEFJ900303M65",IF(G13="KARLA ESTEFANIA SALAZAR FLORES","SAFK9807277N1",IF(G13="ANGEL TERRAZAS MONROY","TEMA7105035N4")))))))))) -> 37675 | P13: =IF(G13="EFREN ABUNDEZ REYNA","PFAEP",IF(G13="LUIS ALEJANDRO HERNANDEZ REYNA","HERL850705AL2",IF(G13="ANA BEATRIZ ESTRADA ARGOTE","EAAA860701UP2",IF(G13="SERGIO ROMERO DURAN","RODS620908QAA",IF(G13="MARIELA OLMOS GAONA","RESICO",IF(G13="LUCIANO MIJAIL ORTEGA MUÑOZ","RIF",IF(G13="GUSTAVO HUMBERTO VELAZCO GALVAN","VEGG9211019T1",IF(G13="JESUS AGUSTIN VELAZQUEZ FLORES","VEFJ900303M65",IF(G13="KARLA ESTEFANIA SALAZAR FLORES","SAFK9807277N1",IF(G13="ANGEL TERRAZAS MONROY","TEMA7105035N4")))))))))) -> RESICO
A14: =IF(D14>0,MONTH(D14),0) -> 1 | B14: =VLOOKUP(A14,[1]Hoja3!$C$3:$D$14,2,FALSE) -> ENERO | C14: 45321 | D14: 45321 | G14: IITS IDENTIFICATION E INFORMATION TRANSPORT SYSTEMS | H14: IIE101203RU0 | I14: =+B14 -> ENERO | J14: 436 | K14: =+J14*0.16 -> 69.76 | N14: =+J14+K14-L14-M14 -> 505.76 | O14: 11289 | P14: MORAL | Q14: ofernandez@iits.com.mx
A15: =IF(D15>0,MONTH(D15),0) -> 2 | B15: =VLOOKUP(A15,[1]Hoja3!$C$3:$D$14,2,FALSE) -> FEBRERO | C15: 45323 | D15: 45323 | G15: EFREN ABUNDEZ REYNA | H15: =IF(G15="EFREN ABUNDEZ REYNA","AURE7306187IA",IF(G15="LUIS ALEJANDRO HERNANDEZ REYNA","HERL850705AL2",IF(G15="ANA BEATRIZ ESTRADA ARGOTE","EAAA860701UP2",IF(G15="SERGIO ROMERO DURAN","RODS620908QAA",IF(G15="MARIELA OLMOS GAONA","OOGM010703NX1",IF(G15="LUCIANO MIJAIL ORTEGA MUÑOZ","OEML881105IK2",IF(G15="GUSTAVO HUMBERTO VELAZCO GALVAN","VEGG9211019T1",IF(G15="JESUS AGUSTIN VELAZQUEZ FLORES","VEFJ900303M65",IF(G15="KARLA ESTEFANIA SALAZAR FLORES","SAFK9807277N1",IF(G15="ANGEL TERRAZAS MONROY","TEMA7105035N4")))))))))) -> AURE7306187IA | I15: =+B15 -> FEBRERO | J15: 1116 | K15: 0 | N15: =+J15+K15-L15-M15 -> 1116 | O15: =IF(G15="EFREN ABUNDEZ REYNA","37295",IF(G15="LUIS ALEJANDRO HERNANDEZ REYNA","HERL850705AL2",IF(G15="ANA BEATRIZ ESTRADA ARGOTE","EAAA860701UP2",IF(G15="SERGIO ROMERO DURAN","RODS620908QAA",IF(G15="MARIELA OLMOS GAONA","37675",IF(G15="LUCIANO MIJAIL ORTEGA MUÑOZ","37297",IF(G15="GUSTAVO HUMBERTO VELAZCO GALVAN","VEGG9211019T1",IF(G15="JESUS AGUSTIN VELAZQUEZ FLORES","VEFJ900303M65",IF(G15="KARLA ESTEFANIA SALAZAR FLORES","SAFK9807277N1",IF(G15="ANGEL TERRAZAS MONROY","TEMA7105035N4")))))))))) -> 37295 | P15: =IF(G15="EFREN ABUNDEZ REYNA","PFAEP",IF(G15="LUIS ALEJANDRO HERNANDEZ REYNA","HERL850705AL2",IF(G15="ANA BEATRIZ ESTRADA ARGOTE","EAAA860701UP2",IF(G15="SERGIO ROMERO DURAN","RODS620908QAA",IF(G15="MARIELA OLMOS GAONA","RESICO",IF(G15="LUCIANO MIJAIL ORTEGA MUÑOZ","RIF",IF(G15="GUSTAVO HUMBERTO VELAZCO GALVAN","VEGG9211019T1",IF(G15="JESUS AGUSTIN VELAZQUEZ FLORES","VEFJ900303M65",IF(G15="KARLA ESTEFANIA SALAZAR FLORES","SAFK9807277N1",IF(G15="ANGEL TERRAZAS MONROY","TEMA7105035N4")))))))))) -> PFAEP
A16: =IF(D16>0,MONTH(D16),0) -> 2 | B16: =VLOOKUP(A16,[1]Hoja3!$C$3:$D$14,2,FALSE) -> FEBRERO | C16: 45323 | D16: 45323 | G16: EFREN ABUNDEZ REYNA | H16: =IF(G16="EFREN ABUNDEZ REYNA","AURE7306187IA",IF(G16="LUIS ALEJANDRO HERNANDEZ REYNA","HERL850705AL2",IF(G16="ANA BEATRIZ ESTRADA ARGOTE","EAAA860701UP2",IF(G16="SERGIO ROMERO DURAN","RODS620908QAA",IF(G16="MARIELA OLMOS GAONA","OOGM010703NX1",IF(G16="LUCIANO MIJAIL ORTEGA MUÑOZ","OEML881105IK2",IF(G16="GUSTAVO HUMBERTO VELAZCO GALVAN","VEGG9211019T1",IF(G16="JESUS AGUSTIN VELAZQUEZ FLORES","VEFJ900303M65",IF(G16="KARLA ESTEFANIA SALAZAR FLORES","SAFK9807277N1",IF(G16="ANGEL TERRAZAS MONROY","TEMA7105035N4")))))))))) -> AURE7306187IA | I16: =+B16 -> FEBRERO | J16: 1116 | K16: 0 | N16: =+J16+K16-L16-M16 -> 1116 | O16: =IF(G16="EFREN ABUNDEZ REYNA","37295",IF(G16="LUIS ALEJANDRO HERNANDEZ REYNA","HERL850705AL2",IF(G16="ANA BEATRIZ ESTRADA ARGOTE","EAAA860701UP2",IF(G16="SERGIO ROMERO DURAN","RODS620908QAA",IF(G16="MARIELA OLMOS GAONA","37675",IF(G16="LUCIANO MIJAIL ORTEGA MUÑOZ","37297",IF(G16="GUSTAVO HUMBERTO VELAZCO GALVAN","VEGG9211019T1",IF(G16="JESUS AGUSTIN VELAZQUEZ FLORES","VEFJ900303M65",IF(G16="KARLA ESTEFANIA SALAZAR FLORES","SAFK9807277N1",IF(G16="ANGEL TERRAZAS MONROY","TEMA7105035N4")))))))))) -> 37295 | P16: =IF(G16="EFREN ABUNDEZ REYNA","PFAEP",IF(G16="LUIS ALEJANDRO HERNANDEZ REYNA","HERL850705AL2",IF(G16="ANA BEATRIZ ESTRADA ARGOTE","EAAA860701UP2",IF(G16="SERGIO ROMERO DURAN","RODS620908QAA",IF(G16="MARIELA OLMOS GAONA","RESICO",IF(G16="LUCIANO MIJAIL ORTEGA MUÑOZ","RIF",IF(G16="GUSTAVO HUMBERTO VELAZCO GALVAN","VEGG9211019T1",IF(G16="JESUS AGUSTIN VELAZQUEZ FLORES","VEFJ900303M65",IF(G16="KARLA ESTEFANIA SALAZAR FLORES","SAFK9807277N1",IF(G16="ANGEL TERRAZAS MONROY","TEMA7105035N4")))))))))) -> PFAEP
A17: =IF(D17>0,MONTH(D17),0) -> 2 | B17: =VLOOKUP(A17,[1]Hoja3!$C$3:$D$14,2,FALSE) -> FEBRERO | C17: 45329 | D17: 45329 | G17: GRISELDA CELINA POOL NOH | H17: PONG860110V5A | I17: =+B17 -> FEBRERO | J17: 1470 | K17: =+J17*0.16 -> 235.2 | N17: =+J17+K17-L17-M17 -> 1705.2 | O17: 22237 | P17: PFAEP | Q17: javier.arcive@gmail.com
A18: =IF(D18>0,MONTH(D18),0) -> 2 | B18: =VLOOKUP(A18,[1]Hoja3!$C$3:$D$14,2,FALSE) -> FEBRERO | C18: 45329 | D18: 45329 | G18: EFREN ABUNDEZ REYNA | H18: =IF(G18="EFREN ABUNDEZ REYNA","AURE7306187IA",IF(G18="LUIS ALEJANDRO HERNANDEZ REYNA","HERL850705AL2",IF(G18="ANA BEATRIZ ESTRADA ARGOTE","EAAA860701UP2",IF(G18="SERGIO ROMERO DURAN","RODS620908QAA",IF(G18="MARIELA OLMOS GAONA","OOGM010703NX1",IF(G18="LUCIANO MIJAIL ORTEGA MUÑOZ","OEML881105IK2",IF(G18="GUSTAVO HUMBERTO VELAZCO GALVAN","VEGG9211019T1",IF(G18="JESUS AGUSTIN VELAZQUEZ FLORES","VEFJ900303M65",IF(G18="KARLA ESTEFANIA SALAZAR FLORES","SAFK9807277N1",IF(G18="ANGEL TERRAZAS MONROY","TEMA7105035N4")))))))))) -> AURE7306187IA | I18: =+B18 -> FEBRERO | J18: 1201 | K18: 0 | N18: =+J18+K18-L18-M18 -> 1201 | O18: =IF(G18="EFREN ABUNDEZ REYNA","37295",IF(G18="LUIS ALEJANDRO HERNANDEZ REYNA","HERL850705AL2",IF(G18="ANA BEATRIZ ESTRADA ARGOTE","EAAA860701UP2",IF(G18="SERGIO ROMERO DURAN","RODS620908QAA",IF(G18="MARIELA OLMOS GAONA","37675",IF(G18="LUCIANO MIJAIL ORTEGA MUÑOZ","37297",IF(G18="GUSTAVO HUMBERTO VELAZCO GALVAN","VEGG9211019T1",IF(G18="JESUS AGUSTIN VELAZQUEZ FLORES","VEFJ900303M65",IF(G18="KARLA ESTEFANIA SALAZAR FLORES","SAFK9807277N1",IF(G18="ANGEL TERRAZAS MONROY","TEMA7105035N4")))))))))) -> 37295 | P18: =IF(G18="EFREN ABUNDEZ REYNA","PFAEP",IF(G18="LUIS ALEJANDRO HERNANDEZ REYNA","HERL850705AL2",IF(G18="ANA BEATRIZ ESTRADA ARGOTE","EAAA860701UP2",IF(G18="SERGIO ROMERO DURAN","RODS620908QAA",IF(G18="MARIELA OLMOS GAONA","RESICO",IF(G18="LUCIANO MIJAIL ORTEGA MUÑOZ","RIF",IF(G18="GUSTAVO HUMBERTO VELAZCO GALVAN","VEGG9211019T1",IF(G18="JESUS AGUSTIN VELAZQUEZ FLORES","VEFJ900303M65",IF(G18="KARLA ESTEFANIA SALAZAR FLORES","SAFK9807277N1",IF(G18="ANGEL TERRAZAS MONROY","TEMA7105035N4")))))))))) -> PFAEP
A19: =IF(D19>0,MONTH(D19),0) -> 2 | B19: =VLOOKUP(A19,[1]Hoja3!$C$3:$D$14,2,FALSE) -> FEBRERO | C19: 45329 | D19: 45329 | G19: MARIELA OLMOS GAONA | H19: =IF(G19="EFREN ABUNDEZ REYNA","AURE7306187IA",IF(G19="LUIS ALEJANDRO HERNANDEZ REYNA","HERL850705AL2",IF(G19="ANA BEATRIZ ESTRADA ARGOTE","EAAA860701UP2",IF(G19="SERGIO ROMERO DURAN","RODS620908QAA",IF(G19="MARIELA OLMOS GAONA","OOGM010703NX1",IF(G19="LUCIANO MIJAIL ORTEGA MUÑOZ","OEML881105IK2",IF(G19="GUSTAVO HUMBERTO VELAZCO GALVAN","VEGG9211019T1",IF(G19="JESUS AGUSTIN VELAZQUEZ FLORES","VEFJ900303M65",IF(G19="KARLA ESTEFANIA SALAZAR FLORES","SAFK9807277N1",IF(G19="ANGEL TERRAZAS MONROY","TEMA7105035N4")))))))))) -> OOGM010703NX1 | I19: =+B19 -> FEBRERO | J19: 5980 | K19: 0 | N19: =+J19+K19-L19-M19 -> 5980 | O19: =IF(G19="EFREN ABUNDEZ REYNA","37295",IF(G19="LUIS ALEJANDRO HERNANDEZ REYNA","HERL850705AL2",IF(G19="ANA BEATRIZ ESTRADA ARGOTE","EAAA860701UP2",IF(G19="SERGIO ROMERO DURAN","RODS620908QAA",IF(G19="MARIELA OLMOS GAONA","37675",IF(G19="LUCIANO MIJAIL ORTEGA MUÑOZ","37297",IF(G19="GUSTAVO HUMBERTO VELAZCO GALVAN","VEGG9211019T1",IF(G19="JESUS AGUSTIN VELAZQUEZ FLORES","VEFJ900303M65",IF(G19="KARLA ESTEFANIA SALAZAR FLORES","SAFK9807277N1",IF(G19="ANGEL TERRAZAS MONROY","TEMA7105035N4")))))))))) -> 37675 | P19: =IF(G19="EFREN ABUNDEZ REYNA","PFAEP",IF(G19="LUIS ALEJANDRO HERNANDEZ REYNA","HERL850705AL2",IF(G19="ANA BEATRIZ ESTRADA ARGOTE","EAAA860701UP2",IF(G19="SERGIO ROMERO DURAN","RODS620908QAA",IF(G19="MARIELA OLMOS GAONA","RESICO",IF(G19="LUCIANO MIJAIL ORTEGA MUÑOZ","RIF",IF(G19="GUSTAVO HUMBERTO VELAZCO GALVAN","VEGG9211019T1",IF(G19="JESUS AGUSTIN VELAZQUEZ FLORES","VEFJ900303M65",IF(G19="KARLA ESTEFANIA SALAZAR FLORES","SAFK9807277N1",IF(G19="ANGEL TERRAZAS MONROY","TEMA7105035N4")))))))))) -> RESICO
A20: =IF(D20>0,MONTH(D20),0) -> 2 | B20: =VLOOKUP(A20,[1]Hoja3!$C$3:$D$14,2,FALSE) -> FEBRERO | C20: 45344 | D20: 45344 | G20: MARIELA OLMOS GAONA | H20: =IF(G20="EFREN ABUNDEZ REYNA","AURE7306187IA",IF(G20="LUIS ALEJANDRO HERNANDEZ REYNA","HERL850705AL2",IF(G20="ANA BEATRIZ ESTRADA ARGOTE","EAAA860701UP2",IF(G20="SERGIO ROMERO DURAN","RODS620908QAA",IF(G20="MARIELA OLMOS GAONA","OOGM010703NX1",IF(G20="LUCIANO MIJAIL ORTEGA MUÑOZ","OEML881105IK2",IF(G20="GUSTAVO HUMBERTO VELAZCO GALVAN","VEGG9211019T1",IF(G20="JESUS AGUSTIN VELAZQUEZ FLORES","VEFJ900303M65",IF(G20="KARLA ESTEFANIA SALAZAR FLORES","SAFK9807277N1",IF(G20="ANGEL TERRAZAS MONROY","TEMA7105035N4")))))))))) -> OOGM010703NX1 | I20: =+B20 -> FEBRERO | J20: 8980 | K20: 0 | N20: =+J20+K20-L20-M20 -> 8980 | O20: =IF(G20="EFREN ABUNDEZ REYNA","37295",IF(G20="LUIS ALEJANDRO HERNANDEZ REYNA","HERL850705AL2",IF(G20="ANA BEATRIZ ESTRADA ARGOTE","EAAA860701UP2",IF(G20="SERGIO ROMERO DURAN","RODS620908QAA",IF(G20="MARIELA OLMOS GAONA","37675",IF(G20="LUCIANO MIJAIL ORTEGA MUÑOZ","37297",IF(G20="GUSTAVO HUMBERTO VELAZCO GALVAN","VEGG9211019T1",IF(G20="JESUS AGUSTIN VELAZQUEZ FLORES","VEFJ900303M65",IF(G20="KARLA ESTEFANIA SALAZAR FLORES","SAFK9807277N1",IF(G20="ANGEL TERRAZAS MONROY","TEMA7105035N4")))))))))) -> 37675 | P20: =IF(G20="EFREN ABUNDEZ REYNA","PFAEP",IF(G20="LUIS ALEJANDRO HERNANDEZ REYNA","HERL850705AL2",IF(G20="ANA BEATRIZ ESTRADA ARGOTE","EAAA860701UP2",IF(G20="SERGIO ROMERO DURAN","RODS620908QAA",IF(G20="MARIELA OLMOS GAONA","RESICO",IF(G20="LUCIANO MIJAIL ORTEGA MUÑOZ","RIF",IF(G20="GUSTAVO HUMBERTO VELAZCO GALVAN","VEGG9211019T1",IF(G20="JESUS AGUSTIN VELAZQUEZ FLORES","VEFJ900303M65",IF(G20="KARLA ESTEFANIA SALAZAR FLORES","SAFK9807277N1",IF(G20="ANGEL TERRAZAS MONROY","TEMA7105035N4")))))))))) -> RESICO
A21: =IF(D21>0,MONTH(D21),0) -> 2 | B21: =VLOOKUP(A21,[1]Hoja3!$C$3:$D$14,2,FALSE) -> FEBRERO | C21: 45344 | D21: 45344 | G21: EFREN ABUNDEZ REYNA | H21: =IF(G21="EFREN ABUNDEZ REYNA","AURE7306187IA",IF(G21="LUIS ALEJANDRO HERNANDEZ REYNA","HERL850705AL2",IF(G21="ANA BEATRIZ ESTRADA ARGOTE","EAAA860701UP2",IF(G21="SERGIO ROMERO DURAN","RODS620908QAA",IF(G21="MARIELA OLMOS GAONA","OOGM010703NX1",IF(G21="LUCIANO MIJAIL ORTEGA MUÑOZ","OEML881105IK2",IF(G21="GUSTAVO HUMBERTO VELAZCO GALVAN","VEGG9211019T1",IF(G21="JESUS AGUSTIN VELAZQUEZ FLORES","VEFJ900303M65",IF(G21="KARLA ESTEFANIA SALAZAR FLORES","SAFK9807277N1",IF(G21="ANGEL TERRAZAS MONROY","TEMA7105035N4")))))))))) -> AURE7306187IA | I21: =+B21 -> FEBRERO | J21: 1777 | K21: 0 | N21: =+J21+K21-L21-M21 -> 1777 | O21: =IF(G21="EFREN ABUNDEZ REYNA","37295",IF(G21="LUIS ALEJANDRO HERNANDEZ REYNA","HERL850705AL2",IF(G21="ANA BEATRIZ ESTRADA ARGOTE","EAAA860701UP2",IF(G21="SERGIO ROMERO DURAN","RODS620908QAA",IF(G21="MARIELA OLMOS GAONA","37675",IF(G21="LUCIANO MIJAIL ORTEGA MUÑOZ","37297",IF(G21="GUSTAVO HUMBERTO VELAZCO GALVAN","VEGG9211019T1",IF(G21="JESUS AGUSTIN VELAZQUEZ FLORES","VEFJ900303M65",IF(G21="KARLA ESTEFANIA SALAZAR FLORES","SAFK9807277N1",IF(G21="ANGEL TERRAZAS MONROY","TEMA7105035N4")))))))))) -> 37295 | P21: =IF(G21="EFREN ABUNDEZ REYNA","PFAEP",IF(G21="LUIS ALEJANDRO HERNANDEZ REYNA","HERL850705AL2",IF(G21="ANA BEATRIZ ESTRADA ARGOTE","EAAA860701UP2",IF(G21="SERGIO ROMERO DURAN","RODS620908QAA",IF(G21="MARIELA OLMOS GAONA","RESICO",IF(G21="LUCIANO MIJAIL ORTEGA MUÑOZ","RIF",IF(G21="GUSTAVO HUMBERTO VELAZCO GALVAN","VEGG9211019T1",IF(G21="JESUS AGUSTIN VELAZQUEZ FLORES","VEFJ900303M65",IF(G21="KARLA ESTEFANIA SALAZAR FLORES","SAFK9807277N1",IF(G21="ANGEL TERRAZAS MONROY","TEMA7105035N4")))))))))) -> PFAEP
A22: =IF(D22>0,MONTH(D22),0) -> 2 | B22: =VLOOKUP(A22,[1]Hoja3!$C$3:$D$14,2,FALSE) -> FEBRERO | C22: 45344 | D22: 45344 | G22: MARIELA OLMOS GAONA | H22: =IF(G22="EFREN ABUNDEZ REYNA","AURE7306187IA",IF(G22="LUIS ALEJANDRO HERNANDEZ REYNA","HERL850705AL2",IF(G22="ANA BEATRIZ ESTRADA ARGOTE","EAAA860701UP2",IF(G22="SERGIO ROMERO DURAN","RODS620908QAA",IF(G22="MARIELA OLMOS GAONA","OOGM010703NX1",IF(G22="LUCIANO MIJAIL ORTEGA MUÑOZ","OEML881105IK2",IF(G22="GUSTAVO HUMBERTO VELAZCO GALVAN","VEGG9211019T1",IF(G22="JESUS AGUSTIN VELAZQUEZ FLORES","VEFJ900303M65",IF(G22="KARLA ESTEFANIA SALAZAR FLORES","SAFK9807277N1",IF(G22="ANGEL TERRAZAS MONROY","TEMA7105035N4")))))))))) -> OOGM010703NX1 | I22: =+B22 -> FEBRERO | J22: 8317 | K22: 0 | N22: =+J22+K22-L22-M22 -> 8317 | O22: =IF(G22="EFREN ABUNDEZ REYNA","37295",IF(G22="LUIS ALEJANDRO HERNANDEZ REYNA","HERL850705AL2",IF(G22="ANA BEATRIZ ESTRADA ARGOTE","EAAA860701UP2",IF(G22="SERGIO ROMERO DURAN","RODS620908QAA",IF(G22="MARIELA OLMOS GAONA","37675",IF(G22="LUCIANO MIJAIL ORTEGA MUÑOZ","37297",IF(G22="GUSTAVO HUMBERTO VELAZCO GALVAN","VEGG9211019T1",IF(G22="JESUS AGUSTIN VELAZQUEZ FLORES","VEFJ900303M65",IF(G22="KARLA ESTEFANIA SALAZAR FLORES","SAFK9807277N1",IF(G22="ANGEL TERRAZAS MONROY","TEMA7105035N4")))))))))) -> 37675 | P22: =IF(G22="EFREN ABUNDEZ REYNA","PFAEP",IF(G22="LUIS ALEJANDRO HERNANDEZ REYNA","HERL850705AL2",IF(G22="ANA BEATRIZ ESTRADA ARGOTE","EAAA860701UP2",IF(G22="SERGIO ROMERO DURAN","RODS620908QAA",IF(G22="MARIELA OLMOS GAONA","RESICO",IF(G22="LUCIANO MIJAIL ORTEGA MUÑOZ","RIF",IF(G22="GUSTAVO HUMBERTO VELAZCO GALVAN","VEGG9211019T1",IF(G22="JESUS AGUSTIN VELAZQUEZ FLORES","VEFJ900303M65",IF(G22="KARLA ESTEFANIA SALAZAR FLORES","SAFK9807277N1",IF(G22="ANGEL TERRAZAS MONROY","TEMA7105035N4")))))))))) -> RESICO
A23: =IF(D23>0,MONTH(D23),0) -> 2 | B23: =VLOOKUP(A23,[1]Hoja3!$C$3:$D$14,2,FALSE) -> FEBRERO | C23: 45344 | D23: 45344 | G23: CAJA POPULAR MEXICANA | H23: CPM960127M3A | I23: =+B23 -> FEBRERO | J23: 431.03448 | K23: =+J23*0.16 -> 68.965517 | N23: =+J23+K23-L23-M23 -> 500 | O23: 37004 | P23: moral no lucrativa | Q23: hedj124791234@gmail.com
A24: =IF(D24>0,MONTH(D24),0) -> 2 | B24: =VLOOKUP(A24,[1]Hoja3!$C$3:$D$14,2,FALSE) -> FEBRERO | C24: 45349 | D24: 45349 | G24: MARIELA OLMOS GAONA | H24: =IF(G24="EFREN ABUNDEZ REYNA","AURE7306187IA",IF(G24="LUIS ALEJANDRO HERNANDEZ REYNA","HERL850705AL2",IF(G24="ANA BEATRIZ ESTRADA ARGOTE","EAAA860701UP2",IF(G24="SERGIO ROMERO DURAN","RODS620908QAA",IF(G24="MARIELA OLMOS GAONA","OOGM010703NX1",IF(G24="LUCIANO MIJAIL ORTEGA MUÑOZ","OEML881105IK2",IF(G24="GUSTAVO HUMBERTO VELAZCO GALVAN","VEGG9211019T1",IF(G24="JESUS AGUSTIN VELAZQUEZ FLORES","VEFJ900303M65",IF(G24="KARLA ESTEFANIA SALAZAR FLORES","SAFK9807277N1",IF(G24="ANGEL TERRAZAS MONROY","TEMA7105035N4")))))))))) -> OOGM010703NX1 | I24: =+B24 -> FEBRERO | J24: 4950 | K24: 0 | N24: =+J24+K24-L24-M24 -> 4950 | O24: =IF(G24="EFREN ABUNDEZ REYNA","37295",IF(G24="LUIS ALEJANDRO HERNANDEZ REYNA","HERL850705AL2",IF(G24="ANA BEATRIZ ESTRADA ARGOTE","EAAA860701UP2",IF(G24="SERGIO ROMERO DURAN","RODS620908QAA",IF(G24="MARIELA OLMOS GAONA","37675",IF(G24="LUCIANO MIJAIL ORTEGA MUÑOZ","37297",IF(G24="GUSTAVO HUMBERTO VELAZCO GALVAN","VEGG9211019T1",IF(G24="JESUS AGUSTIN VELAZQUEZ FLORES","VEFJ900303M65",IF(G24="KARLA ESTEFANIA SALAZAR FLORES","SAFK9807277N1",IF(G24="ANGEL TERRAZAS MONROY","TEMA7105035N4")))))))))) -> 37675 | P24: =IF(G24="EFREN ABUNDEZ REYNA","PFAEP",IF(G24="LUIS ALEJANDRO HERNANDEZ REYNA","HERL850705AL2",IF(G24="ANA BEATRIZ ESTRADA ARGOTE","EAAA860701UP2",IF(G24="SERGIO ROMERO DURAN","RODS620908QAA",IF(G24="MARIELA OLMOS GAONA","RESICO",IF(G24="LUCIANO MIJAIL ORTEGA MUÑOZ","RIF",IF(G24="GUSTAVO HUMBERTO VELAZCO GALVAN","VEGG9211019T1",IF(G24="JESUS AGUSTIN VELAZQUEZ FLORES","VEFJ900303M65",IF(G24="KARLA ESTEFANIA SALAZAR FLORES","SAFK9807277N1",IF(G24="ANGEL TERRAZAS MONROY","TEMA7105035N4")))))))))) -> RESICO
A25: =IF(D25>0,MONTH(D25),0) -> 1 | B25: =VLOOKUP(A25,[1]Hoja3!$C$3:$D$14,2,FALSE) -> ENERO | C25: 45322 | D25: 45322 | G25: PUBLICO EN GENERAL | H25: =IF(G25="EFREN ABUNDEZ REYNA","AURE7306187IA",IF(G25="LUIS ALEJANDRO HERNANDEZ REYNA","HERL850705AL2",IF(G25="ANA BEATRIZ ESTRADA ARGOTE","EAAA860701UP2",IF(G25="SERGIO ROMERO DURAN","RODS620908QAA",IF(G25="MARIELA OLMOS GAONA","OOGM010703NX1",IF(G25="LUCIANO MIJAIL ORTEGA MUÑOZ","OEML881105IK2",IF(G25="GUSTAVO HUMBERTO VELAZCO GALVAN","VEGG9211019T1",IF(G25="JESUS AGUSTIN VELAZQUEZ FLORES","VEFJ900303M65",IF(G25="KARLA ESTEFANIA SALAZAR FLORES","SAFK9807277N1",IF(G25="ANGEL TERRAZAS MONROY","TEMA7105035N4")))))))))) -> FALSE | I25: =+B25 -> ENERO | J25: 260145 | K25: 0 | N25: =+J25+K25-L25-M25 -> 260145 | O25: =IF(G25="EFREN ABUNDEZ REYNA","37295",IF(G25="LUIS ALEJANDRO HERNANDEZ REYNA","HERL850705AL2",IF(G25="ANA BEATRIZ ESTRADA ARGOTE","EAAA860701UP2",IF(G25="SERGIO ROMERO DURAN","RODS620908QAA",IF(G25="MARIELA OLMOS GAONA","37675",IF(G25="LUCIANO MIJAIL ORTEGA MUÑOZ","37297",IF(G25="GUSTAVO HUMBERTO VELAZCO GALVAN","VEGG9211019T1",IF(G25="JESUS AGUSTIN VELAZQUEZ FLORES","VEFJ900303M65",IF(G25="KARLA ESTEFANIA SALAZAR FLORES","SAFK9807277N1",IF(G25="ANGEL TERRAZAS MONROY","TEMA7105035N4")))))))))) -> FALSE | P25: =IF(G25="EFREN ABUNDEZ REYNA","PFAEP",IF(G25="LUIS ALEJANDRO HERNANDEZ REYNA","HERL850705AL2",IF(G25="ANA BEATRIZ ESTRADA ARGOTE","EAAA860701UP2",IF(G25="SERGIO ROMERO DURAN","RODS620908QAA",IF(G25="MARIELA OLMOS GAONA","RESICO",IF(G25="LUCIANO MIJAIL ORTEGA MUÑOZ","RIF",IF(G25="GUSTAVO HUMBERTO VELAZCO GALVAN","VEGG9211019T1",IF(G25="JESUS AGUSTIN VELAZQUEZ FLORES","VEFJ900303M65",IF(G25="KARLA ESTEFANIA SALAZAR FLORES","SAFK9807277N1",IF(G25="ANGEL TERRAZAS MONROY","TEMA7105035N4")))))))))) -> FALSE
A26: =IF(D26>0,MONTH(D26),0) -> 3 | B26: =VLOOKUP(A26,[1]Hoja3!$C$3:$D$14,2,FALSE) -> MARZO | C26: 45358 | D26: 45358 | G26: MARIELA OLMOS GAONA | H26: =IF(G26="EFREN ABUNDEZ REYNA","AURE7306187IA",IF(G26="LUIS ALEJANDRO HERNANDEZ REYNA","HERL850705AL2",IF(G26="ANA BEATRIZ ESTRADA ARGOTE","EAAA860701UP2",IF(G26="SERGIO ROMERO DURAN","RODS620908QAA",IF(G26="MARIELA OLMOS GAONA","OOGM010703NX1",IF(G26="LUCIANO MIJAIL ORTEGA MUÑOZ","OEML881105IK2",IF(G26="GUSTAVO HUMBERTO VELAZCO GALVAN","VEGG9211019T1",IF(G26="JESUS AGUSTIN VELAZQUEZ FLORES","VEFJ900303M65",IF(G26="KARLA ESTEFANIA SALAZAR FLORES","SAFK9807277N1",IF(G26="ANGEL TERRAZAS MONROY","TEMA7105035N4")))))))))) -> OOGM010703NX1 | I26: =+B26 -> MARZO | J26: 7125 | K26: 0 | N26: =+J26+K26-L26-M26 -> 7125 | O26: =IF(G26="EFREN ABUNDEZ REYNA","37295",IF(G26="LUIS ALEJANDRO HERNANDEZ REYNA","HERL850705AL2",IF(G26="ANA BEATRIZ ESTRADA ARGOTE","EAAA860701UP2",IF(G26="SERGIO ROMERO DURAN","RODS620908QAA",IF(G26="MARIELA OLMOS GAONA","37675",IF(G26="LUCIANO MIJAIL ORTEGA MUÑOZ","37297",IF(G26="GUSTAVO HUMBERTO VELAZCO GALVAN","VEGG9211019T1",IF(G26="JESUS AGUSTIN VELAZQUEZ FLORES","VEFJ900303M65",IF(G26="KARLA ESTEFANIA SALAZAR FLORES","SAFK9807277N1",IF(G26="ANGEL TERRAZAS MONROY","TEMA7105035N4")))))))))) -> 37675 | P26: =IF(G26="EFREN ABUNDEZ REYNA","PFAEP",IF(G26="LUIS ALEJANDRO HERNANDEZ REYNA","HERL850705AL2",IF(G26="ANA BEATRIZ ESTRADA ARGOTE","EAAA860701UP2",IF(G26="SERGIO ROMERO DURAN","RODS620908QAA",IF(G26="MARIELA OLMOS GAONA","RESICO",IF(G26="LUCIANO MIJAIL ORTEGA MUÑOZ","RIF",IF(G26="GUSTAVO HUMBERTO VELAZCO GALVAN","VEGG9211019T1",IF(G26="JESUS AGUSTIN VELAZQUEZ FLORES","VEFJ900303M65",IF(G26="KARLA ESTEFANIA SALAZAR FLORES","SAFK9807277N1",IF(G26="ANGEL TERRAZAS MONROY","TEMA7105035N4")))))))))) -> RESICO
